Workbook

Sheet Summary
B2: Market Share
B4: Country | C4: (All)
B6: Sum of Total Required Supply | C6: Column Labels
B7: Row Labels | C7: R21/Matrix-M | D7: RTS,S/AS01 | E7: TBD
B8: 2024 | C8: 0.44496789 | D8: 0.55503211 | E8: 0
B9: 2025 | C9: 0.82343204 | D9: 0.17656796 | E9: 0
B10: 2026 | C10: 0.84244112 | D10: 0.14512379 | E10: 0.012435089
B11: 2027 | C11: 0.81400751 | D11: 0.14106431 | E11: 0.044928181
B12: 2028 | C12: 0.81795613 | D12: 0.11376808 | E12: 0.06827579
B13: 2029 | C13: 0.81928106 | D13: 0.10831159 | E13: 0.072407345
B14: 2030 | C14: 0.81856245 | D14: 0.10866959 | E14: 0.072767954
B15: 2031 | C15: 0.8182579 | D15: 0.10860067 | E15: 0.073141434
B16: 2032 | C16: 0.81827039 | D16: 0.10841241 | E16: 0.073317203
B17: 2033 | C17: 0.81828895 | D17: 0.10809213 | E17: 0.073618918
B18: 2034 | C18: 0.81857558 | D18: 0.10735761 | E18: 0.074066809
B19: 2035 | C19: 0.81873515 | D19: 0.10670573 | E19: 0.074559111
B20: Grand Total | C20: 0.81690107 | D20: 0.12094199 | E20: 0.062156941
B25: WAP
B27: Country | C27: (All)
B29: Row Labels | C29: Average of WAP ($/Dose)
B30: 2024 | C30: 7.8262972
B31: 2025 | C31: 5.1490418
B32: 2026 | C32: 4.9266057
B33: 2027 | C33: 4.1162574
B34: 2028 | C34: 3.2186738
B35: 2029 | C35: 3.2077063
B36: 2030 | C36: 3.2084259
B37: 2031 | C37: 3.2082873
B38: 2032 | C38: 3.2079089
B39: 2033 | C39: 3.2072652
B40: 2034 | C40: 3.2057888
B41: 2035 | C41: 3.2044785
B42: Grand Total | C42: 3.5400948
B45: Market Size
B47: Market size (2026-20230), Price of R21 reduces to $2.99 post 2027 | E47: Market size (2026-20230), Price of R21 remains $3.90 | H47: Potential Savings due to price reduction (Mn USD)
B48: Market size (Mn USD) | C48: =SUM(C56:C60) -> 1096.3838 | E48: Market size (Mn USD) | F48: 1296.417 | H48: =C48-F48 -> -200.03322
B49: Market size (Mn doses) | C49: =SUM(D56:D60) -> 296.42636 | E49: Market size (Mn doses) | F49: 296.42636
B51: Country | C51: (All)
B53: Row Labels | C53: Sum of Market Size (Mn USD) | D53: Sum of Market Size (Mn doses)
B54: 2024 | C54: 46.106854 | D54: 5.8912731
...

Sheet Master Data
C4: Year | D4: Country | E4: ISO | F4: WHO Region | G4: Unicef Region | H4: WB Status | I4: Price Tier | J4: Gavi Co-financing | K4: Gavi Eligibility | L4: Vaccine | M4: Vaccine Sub-type | N4: Product Introduction Date | O4: Vaccine Introduction Date | P4: Brand Name | Q4: Product Mapping | R4: Year_product | S4: Price (USD $/Dose) | T4: Price X Volume | U4: Routine/Campaign | V4: Gender | W4: Total Required Supply
C5: 2024 | D5: Burkina Faso | E5: BFA | F5: AFRO | G5: SSA | H5: Low Income | I5: UNICEF | J5: Initial self-financing | K5: Eligible | L5: Malaria | M5: Malaria | N5: Jan 2024 | O5: Jan 2024 | P5: RTS,S/AS01 | Q5: RTS,S/AS01 | R5: 2024RTS,S/AS01 | S5: =_xlfn.XLOOKUP(R5,'Price Assumptions'!E:E,'Price Assumptions'!G:G) -> 10.974 | T5: =S5*W5 -> 5936227.7 | U5: Routine | V5: Both | W5: 540935.64
C6: 2024 | D6: CAR | E6: CAF | F6: AFRO | G6: SSA | H6: Low Income | I6: UNICEF | J6: Initial self-financing | K6: Eligible | L6: Malaria | M6: Malaria | N6: Jan 2024 | O6: Jan 2024 | P6: CYVAC | Q6: R21/Matrix-M | R6: 2024R21/Matrix-M | S6: =_xlfn.XLOOKUP(R6,'Price Assumptions'!E:E,'Price Assumptions'!G:G) -> 3.9 | T6: =S6*W6 -> 501379.63 | U6: Routine | V6: Both | W6: 128558.88
C7: 2024 | D7: Chad | E7: TCD | F7: AFRO | G7: SSA | H7: Low Income | I7: UNICEF | J7: Initial self-financing | K7: Eligible | L7: Malaria | M7: Malaria | N7: Oct 2024 | O7: Oct 2024 | P7: CYVAC | Q7: R21/Matrix-M | R7: 2024R21/Matrix-M | S7: =_xlfn.XLOOKUP(R7,'Price Assumptions'!E:E,'Price Assumptions'!G:G) -> 3.9 | T7: =S7*W7 -> 196879.57 | U7: Routine | V7: Both | W7: 50481.942
C8: 2024 | D8: DRC | E8: COD | F8: AFRO | G8: SSA | H8: Low Income | I8: UNICEF | J8: Initial self-financing | K8: Eligible | L8: Malaria | M8: Malaria | N8: Nov 2024 | O8: Nov 2024 | P8: CYVAC | Q8: R21/Matrix-M | R8: 2024R21/Matrix-M | S8: =_xlfn.XLOOKUP(R8,'Price Assumptions'!E:E,'Price Assumptions'!G:G) -> 3.9 | T8: =S8*W8 -> 1290126 | U8: Routine | V8: Both | W8: 330801.54
C9: 2024 | D9: Liberia | E9: LBR | F9: AFRO | G9: SSA | H9: Low Income | I9: UNICEF | J9: Initial self-financing | K9: Eligible | L9: Malaria | M9: Malaria | N9: Apr 2024 | O9: Apr 2024 | P9: RTS,S/AS01 | Q9: RTS,S/AS01 | R9: 2024RTS,S/AS01 | S9: =_xlfn.XLOOKUP(R9,'Price Assumptions'!E:E,'Price Assumptions'!G:G) -> 10.974 | T9: =S9*W9 -> 999221.33 | U9: Routine | V9: Both | W9: 91053.52
C10: 2024 | D10: Malawi | E10: MWI | F10: AFRO | G10: SSA | H10: Low Income | I10: UNICEF | J10: Initial self-financing | K10: Eligible | L10: Malaria | M10: Malaria | N10: Jan 2024 | O10: Jan 2024 | P10: RTS,S/AS01 | Q10: RTS,S/AS01 | R10: 2024RTS,S/AS01 | S10: =_xlfn.XLOOKUP(R10,'Price Assumptions'!E:E,'Price Assumptions'!G:G) -> 10.974 | T10: =S10*W10 -> 5720528.3 | U10: Routine | V10: Both | W10: 521280.14
C11: 2024 | D11: Mozambique | E11: MOZ | F11: AFRO | G11: SSA | H11: Low Income | I11: UNICEF | J11: Initial self-financing | K11: Eligible | L11: Malaria | M11: Malaria | N11: Jul 2024 | O11: Jul 2024 | P11: CYVAC | Q11: R21/Matrix-M | R11: 2024R21/Matrix-M | S11: =_xlfn.XLOOKUP(R11,'Price Assumptions'!E:E,'Price Assumptions'!G:G) -> 3.9 | T11: =S11*W11 -> 978666.32 | U11: Routine | V11: Both | W11: 250940.08
C12: 2024 | D12: Niger | E12: NER | F12: AFRO | G12: SSA | H12: Low Income | I12: UNICEF | J12: Initial self-financing | K12: Eligible | L12: Malaria | M12: Malaria | N12: Jul 2024 | O12: Jul 2024 | P12: RTS,S/AS01 | Q12: RTS,S/AS01 | R12: 2024RTS,S/AS01 | S12: =_xlfn.XLOOKUP(R12,'Price Assumptions'!E:E,'Price Assumptions'!G:G) -> 10.974 | T12: =S12*W12 -> 5374392.3 | U12: Routine | V12: Both | W12: 489738.69
C13: 2024 | D13: Sierra Leone | E13: SLE | F13: AFRO | G13: SSA | H13: Low Income | I13: UNICEF | J13: Initial self-financing | K13: Eligible | L13: Malaria | M13: Malaria | N13: Mar 2024 | O13: Mar 2024 | P13: RTS,S/AS01 | Q13: RTS,S/AS01 | R13: 2024RTS,S/AS01 | S13: =_xlfn.XLOOKUP(R13,'Price Assumptions'!E:E,'Price Assumptions'!G:G) -> 10.974 | T13: =S13*W13 -> 5614138.3 | U13: Routine | V13: Both | W13: 511585.41
C14: 2024 | D14: South Sudan | E14: SSD | F14: AFRO | G14: SSA | H14: Low Income | I14: UNICEF | J14: Initial self-financing | K14: Eligible | L14: Malaria | M14: Malaria | N14: Jul 2024 | O14: Jul 2024 | P14: CYVAC | Q14: R21/Matrix-M | R14: 2024R21/Matrix-M | S14: =_xlfn.XLOOKUP(R14,'Price Assumptions'!E:E,'Price Assumptions'!G:G) -> 3.9 | T14: =S14*W14 -> 410050.85 | U14: Routine | V14: Both | W14: 105141.24
C15: 2024 | D15: Sudan | E15: SDN | F15: EMRO | G15: MENA | H15: Low Income | I15: UNICEF | J15: Initial self-financing | K15: Eligible | L15: Malaria | M15: Malaria | N15: Nov 2024 | O15: Nov 2024 | P15: CYVAC | Q15: R21/Matrix-M | R15: 2024R21/Matrix-M | S15: =_xlfn.XLOOKUP(R15,'Price Assumptions'!E:E,'Price Assumptions'!G:G) -> 3.9 | T15: =S15*W15 -> 300350.13 | U15: Routine | V15: Both | W15: 77012.855
C16: 2025 | D16: Burkina Faso | E16: BFA | F16: AFRO | G16: SSA | H16: Low Income | I16: UNICEF | J16: Initial self-financing | K16: Eligible | L16: Malaria | M16: Malaria | N16: - | O16: Jan 2024 | P16: CYVAC | Q16: R21/Matrix-M | R16: 2025R21/Matrix-M | S16: =_xlfn.XLOOKUP(R16,'Price Assumptions'!E:E,'Price Assumptions'!G:G) -> 3.9 | T16: =S16*W16 -> 2268649.7 | U16: Routine | V16: Both | W16: 581705.04
C17: 2025 | D17: Burkina Faso | E17: BFA | F17: AFRO | G17: SSA | H17: Low Income | I17: UNICEF | J17: Initial self-financing | K17: Eligible | L17: Malaria | M17: Malaria | N17: Jan 2024 | O17: Jan 2024 | P17: RTS,S/AS01 | Q17: RTS,S/AS01 | R17: 2025RTS,S/AS01 | S17: =_xlfn.XLOOKUP(R17,'Price Assumptions'!E:E,'Price Assumptions'!G:G) -> 10.974 | T17: =S17*W17 -> 6731075.9 | U17: Routine | V17: Both | W17: 613365.76
C18: 2025 | D18: Burundi | E18: BDI | F18: AFRO | G18: SSA | H18: Low Income | I18: UNICEF | J18: Initial self-financing | K18: Eligible | L18: Malaria | M18: Malaria | N18: - | O18: - | Q18: RTS,S/AS01 | R18: 2025RTS,S/AS01 | S18: =_xlfn.XLOOKUP(R18,'Price Assumptions'!E:E,'Price Assumptions'!G:G) -> 10.974 | T18: =S18*W18 -> 1956751.1 | U18: Routine | V18: Both | W18: 178307.91
C19: 2025 | D19: CAR | E19: CAF | F19: AFRO | G19: SSA | H19: Low Income | I19: UNICEF | J19: Initial self-financing | K19: Eligible | L19: Malaria | M19: Malaria | N19: Jan 2024 | O19: Jan 2024 | P19: CYVAC | Q19: R21/Matrix-M | R19: 2025R21/Matrix-M | S19: =_xlfn.XLOOKUP(R19,'Price Assumptions'!E:E,'Price Assumptions'!G:G) -> 3.9 | T19: =S19*W19 -> 1430384.6 | U19: Routine | V19: Both | W19: 366765.29
C20: 2025 | D20: Chad | E20: TCD | F20: AFRO | G20: SSA | H20: Low Income | I20: UNICEF | J20: Initial self-financing | K20: Eligible | L20: Malaria | M20: Malaria | N20: Oct 2024 | O20: Oct 2024 | P20: CYVAC | Q20: R21/Matrix-M | R20: 2025R21/Matrix-M | S20: =_xlfn.XLOOKUP(R20,'Price Assumptions'!E:E,'Price Assumptions'!G:G) -> 3.9 | T20: =S20*W20 -> 1300755 | U20: Routine | V20: Both | W20: 333526.92
C21: 2025 | D21: DRC | E21: COD | F21: AFRO | G21: SSA | H21: Low Income | I21: UNICEF | J21: Initial self-financing | K21: Eligible | L21: Malaria | M21: Malaria | N21: Nov 2024 | O21: Nov 2024 | P21: CYVAC | Q21: R21/Matrix-M | R21: 2025R21/Matrix-M | S21: =_xlfn.XLOOKUP(R21,'Price Assumptions'!E:E,'Price Assumptions'!G:G) -> 3.9 | T21: =S21*W21 -> 21746481 | U21: Routine | V21: Both | W21: 5576020.7
C22: 2025 | D22: Ethiopia | E22: ETH | F22: AFRO | G22: SSA | H22: Low Income | I22: UNICEF | J22: Initial self-financing | K22: Eligible | L22: Malaria | M22: Malaria | N22: - | O22: - | Q22: R21/Matrix-M | R22: 2025R21/Matrix-M | S22: =_xlfn.XLOOKUP(R22,'Price Assumptions'!E:E,'Price Assumptions'!G:G) -> 3.9 | T22: =S22*W22 -> 1894596.9 | U22: Routine | V22: Both | W22: 485794.08
C23: 2025 | D23: Guinea-Bissau | E23: GNB | F23: AFRO | G23: SSA | H23: Low Income | I23: UNICEF | J23: Initial self-financing | K23: Eligible | L23: Malaria | M23: Malaria | N23: - | O23: - | Q23: RTS,S/AS01 | R23: 2025RTS,S/AS01 | S23: =_xlfn.XLOOKUP(R23,'Price Assumptions'!E:E,'Price Assumptions'!G:G) -> 10.974 | T23: =S23*W23 -> 25081.519 | U23: Routine | V23: Both | W23: 2285.5403
C24: 2025 | D24: Liberia | E24: LBR | F24: AFRO | G24: SSA | H24: Low Income | I24: UNICEF | J24: Initial self-financing | K24: Eligible | L24: Malaria | M24: Malaria | N24: Apr 2024 | O24: Apr 2024 | P24: RTS,S/AS01 | Q24: RTS,S/AS01 | R24: 2025RTS,S/AS01 | S24: =_xlfn.XLOOKUP(R24,'Price Assumptions'!E:E,'Price Assumptions'!G:G) -> 10.974 | T24: =S24*W24 -> 3042720.8 | U24: Routine | V24: Both | W24: 277266.34
C25: 2025 | D25: Malawi | E25: MWI | F25: AFRO | G25: SSA | H25: Low Income | I25: UNICEF | J25: Initial self-financing | K25: Eligible | L25: Malaria | M25: Malaria | N25: Jan 2024 | O25: Jan 2024 | P25: RTS,S/AS01 | Q25: RTS,S/AS01 | R25: 2025RTS,S/AS01 | S25: =_xlfn.XLOOKUP(R25,'Price Assumptions'!E:E,'Price Assumptions'!G:G) -> 10.974 | T25: =S25*W25 -> 6123322.5 | U25: Routine | V25: Both | W25: 557984.55
C26: 2025 | D26: Mali | E26: MLI | F26: AFRO | G26: SSA | H26: Low Income | I26: UNICEF | J26: Initial self-financing | K26: Eligible | L26: Malaria | M26: Malaria | N26: - | O26: - | Q26: R21/Matrix-M | R26: 2025R21/Matrix-M | S26: =_xlfn.XLOOKUP(R26,'Price Assumptions'!E:E,'Price Assumptions'!G:G) -> 3.9 | T26: =S26*W26 -> 1315397.5 | U26: Routine | V26: Both | W26: 337281.4
C27: 2025 | D27: Mozambique | E27: MOZ | F27: AFRO | G27: SSA | H27: Low Income | I27: UNICEF | J27: Initial self-financing | K27: Eligible | L27: Malaria | M27: Malaria | N27: Jul 2024 | O27: Jul 2024 | P27: CYVAC | Q27: R21/Matrix-M | R27: 2025R21/Matrix-M | S27: =_xlfn.XLOOKUP(R27,'Price Assumptions'!E:E,'Price Assumptions'!G:G) -> 3.9 | T27: =S27*W27 -> 4476457.5 | U27: Routine | V27: Both | W27: 1147809.6
C28: 2025 | D28: Niger | E28: NER | F28: AFRO | G28: SSA | H28: Low Income | I28: UNICEF | J28: Initial self-financing | K28: Eligible | L28: Malaria | M28: Malaria | N28: Jul 2024 | O28: Jul 2024 | P28: RTS,S/AS01 | Q28: RTS,S/AS01 | R28: 2025RTS,S/AS01 | S28: =_xlfn.XLOOKUP(R28,'Price Assumptions'!E:E,'Price Assumptions'!G:G) -> 10.974 | T28: =S28*W28 -> 6897715.8 | U28: Routine | V28: Both | W28: 628550.74
C29: 2025 | D29: Sierra Leone | E29: SLE | F29: AFRO | G29: SSA | H29: Low Income | I29: UNICEF | J29: Initial self-financing | K29: Eligible | L29: Malaria | M29: Malaria | N29: Mar 2024 | O29: Mar 2024 | P29: RTS,S/AS01 | Q29: RTS,S/AS01 | R29: 2025RTS,S/AS01 | S29: =_xlfn.XLOOKUP(R29,'Price Assumptions'!E:E,'Price Assumptions'!G:G) -> 10.974 | T29: =S29*W29 -> 7835065.6 | U29: Routine | V29: Both | W29: 713966.25
C30: 2025 | D30: South Sudan | E30: SSD | F30: AFRO | G30: SSA | H30: Low Income | I30: UNICEF | J30: Initial self-financing | K30: Eligible | L30: Malaria | M30: Malaria | N30: Jul 2024 | O30: Jul 2024 | P30: CYVAC | Q30: R21/Matrix-M | R30: 2025R21/Matrix-M | S30: =_xlfn.XLOOKUP(R30,'Price Assumptions'!E:E,'Price Assumptions'!G:G) -> 3.9 | T30: =S30*W30 -> 1551742.7 | U30: Routine | V30: Both | W30: 397882.75
C31: 2025 | D31: Sudan | E31: SDN | F31: EMRO | G31: MENA | H31: Low Income | I31: UNICEF | J31: Initial self-financing | K31: Eligible | L31: Malaria | M31: Malaria | N31: Nov 2024 | O31: Nov 2024 | P31: CYVAC | Q31: R21/Matrix-M | R31: 2025R21/Matrix-M | S31: =_xlfn.XLOOKUP(R31,'Price Assumptions'!E:E,'Price Assumptions'!G:G) -> 3.9 | T31: =S31*W31 -> 2699728.1 | U31: Routine | V31: Both | W31: 692237.97
C32: 2025 | D32: Togo | E32: TGO | F32: AFRO | G32: SSA | H32: Low Income | I32: UNICEF | J32: Initial self-financing | K32: Eligible | L32: Malaria | M32: Malaria | N32: - | O32: - | Q32: R21/Matrix-M | R32: 2025R21/Matrix-M | S32: =_xlfn.XLOOKUP(R32,'Price Assumptions'!E:E,'Price Assumptions'!G:G) -> 3.9 | T32: =S32*W32 -> 366690.33 | U32: Routine | V32: Both | W32: 94023.161
C33: 2025 | D33: Uganda | E33: UGA | F33: AFRO | G33: SSA | H33: Low Income | I33: UNICEF | J33: Initial self-financing | K33: Eligible | L33: Malaria | M33: Malaria | N33: - | O33: - | Q33: R21/Matrix-M | R33: 2025R21/Matrix-M | S33: =_xlfn.XLOOKUP(R33,'Price Assumptions'!E:E,'Price Assumptions'!G:G) -> 3.9 | T33: =S33*W33 -> 12683439 | U33: Routine | V33: Both | W33: 3252163.9
C34: 2026 | D34: Burundi | E34: BDI | F34: AFRO | G34: SSA | H34: Low Income | I34: UNICEF | J34: Initial self-financing | K34: Eligible | L34: Malaria | M34: Malaria | N34: - | O34: - | Q34: RTS,S/AS01 | R34: 2026RTS,S/AS01 | S34: =_xlfn.XLOOKUP(R34,'Price Assumptions'!E:E,'Price Assumptions'!G:G) -> 10.974 | T34: =S34*W34 -> 6783436.4 | U34: Routine | V34: Both | W34: 618137.09
C35: 2026 | D35: CAR | E35: CAF | F35: AFRO | G35: SSA | H35: Low Income | I35: UNICEF | J35: Initial self-financing | K35: Eligible | L35: Malaria | M35: Malaria | N35: Jan 2024 | O35: Jan 2024 | P35: CYVAC | Q35: R21/Matrix-M | R35: 2026R21/Matrix-M | S35: =_xlfn.XLOOKUP(R35,'Price Assumptions'!E:E,'Price Assumptions'!G:G) -> 3.9 | T35: =S35*W35 -> 1552778 | U35: Routine | V35: Both | W35: 398148.21
C36: 2026 | D36: Chad | E36: TCD | F36: AFRO | G36: SSA | H36: Low Income | I36: UNICEF | J36: Initial self-financing | K36: Eligible | L36: Malaria | M36: Malaria | N36: Oct 2024 | O36: Oct 2024 | P36: CYVAC | Q36: R21/Matrix-M | R36: 2026R21/Matrix-M | S36: =_xlfn.XLOOKUP(R36,'Price Assumptions'!E:E,'Price Assumptions'!G:G) -> 3.9 | T36: =S36*W36 -> 3764764.4 | U36: Routine | V36: Both | W36: 965324.2
C37: 2026 | D37: DRC | E37: COD | F37: AFRO | G37: SSA | H37: Low Income | I37: UNICEF | J37: Initial self-financing | K37: Eligible | L37: Malaria | M37: Malaria | N37: Nov 2024 | O37: Nov 2024 | P37: CYVAC | Q37: R21/Matrix-M | R37: 2026R21/Matrix-M | S37: =_xlfn.XLOOKUP(R37,'Price Assumptions'!E:E,'Price Assumptions'!G:G) -> 3.9 | T37: =S37*W37 -> 31554369 | U37: Routine | V37: Both | W37: 8090863.8
C38: 2026 | D38: Gambia | E38: GMB | F38: AFRO | G38: SSA | H38: Low Income | I38: UNICEF | J38: Initial self-financing | K38: Eligible | L38: Malaria | M38: Malaria | N38: - | O38: - | Q38: R21/Matrix-M | R38: 2026R21/Matrix-M | S38: =_xlfn.XLOOKUP(R38,'Price Assumptions'!E:E,'Price Assumptions'!G:G) -> 3.9 | T38: =S38*W38 -> 46621.594 | U38: Routine | V38: Both | W38: 11954.255
C39: 2026 | D39: Liberia | E39: LBR | F39: AFRO | G39: SSA | H39: Low Income | I39: UNICEF | J39: Initial self-financing | K39: Eligible | L39: Malaria | M39: Malaria | N39: Apr 2024 | O39: Apr 2024 | P39: RTS,S/AS01 | Q39: RTS,S/AS01 | R39: 2026RTS,S/AS01 | S39: =_xlfn.XLOOKUP(R39,'Price Assumptions'!E:E,'Price Assumptions'!G:G) -> 10.974 | T39: =S39*W39 -> 4831770.6 | U39: Routine | V39: Both | W39: 440292.57
C40: 2026 | D40: Malawi | E40: MWI | F40: AFRO | G40: SSA | H40: Low Income | I40: UNICEF | J40: Initial self-financing | K40: Eligible | L40: Malaria | M40: Malaria | N40: Jan 2024 | O40: Jan 2024 | P40: RTS,S/AS01 | Q40: RTS,S/AS01 | R40: 2026RTS,S/AS01 | S40: =_xlfn.XLOOKUP(R40,'Price Assumptions'!E:E,'Price Assumptions'!G:G) -> 10.974 | T40: =S40*W40 -> 16290383 | U40: Routine | V40: Both | W40: 1484452.6
C41: 2026 | D41: Mali | E41: MLI | F41: AFRO | G41: SSA | H41: Low Income | I41: UNICEF | J41: Initial self-financing | K41: Eligible | L41: Malaria | M41: Malaria | N41: - | O41: - | Q41: R21/Matrix-M | R41: 2026R21/Matrix-M | S41: =_xlfn.XLOOKUP(R41,'Price Assumptions'!E:E,'Price Assumptions'!G:G) -> 3.9 | T41: =S41*W41 -> 5136557.4 | U41: Routine | V41: Both | W41: 1317066
C42: 2026 | D42: Mozambique | E42: MOZ | F42: AFRO | G42: SSA | H42: Low Income | I42: UNICEF | J42: Initial self-financing | K42: Eligible | L42: Malaria | M42: Malaria | N42: Jul 2024 | O42: Jul 2024 | P42: CYVAC | Q42: R21/Matrix-M | R42: 2026R21/Matrix-M | S42: =_xlfn.XLOOKUP(R42,'Price Assumptions'!E:E,'Price Assumptions'!G:G) -> 3.9 | T42: =S42*W42 -> 8787908.5 | U42: Routine | V42: Both | W42: 2253309.9
C43: 2026 | D43: Niger | E43: NER | F43: AFRO | G43: SSA | H43: Low Income | I43: UNICEF | J43: Initial self-financing | K43: Eligible | L43: Malaria | M43: Malaria | N43: Jul 2024 | O43: Jul 2024 | P43: RTS,S/AS01 | Q43: RTS,S/AS01 | R43: 2026RTS,S/AS01 | S43: =_xlfn.XLOOKUP(R43,'Price Assumptions'!E:E,'Price Assumptions'!G:G) -> 10.974 | T43: =S43*W43 -> 19257087 | U43: Routine | V43: Both | W43: 1754792
...

Sheet Price Assumptions
C3: Price Data - RTS,S/AS01
C4: Year | D4: Product | E4: Code | F4: Price (local currency)/Dose | G4: Price(USD$)/Dose | J4: RTS,S/AS01 | K4: RTS,S/AS01
C5: 2024 | D5: RTS,S/AS01 | E5: =C5&D5 -> 2024RTS,S/AS01 | F5: 9.3 | G5: =1.18*F5 -> 10.974 | J5: CYVAC | K5: R21/Matrix-M | AI5: Country | AJ5: ISO Code | AK5: Antigen | AL5: Product | AM5: Product Price | AN5: Year | AO5: Volume | AP5: Value
C6: 2025 | D6: RTS,S/AS01 | E6: =C6&D6 -> 2025RTS,S/AS01 | F6: 9.3 | G6: =1.18*F6 -> 10.974
C7: 2026 | D7: RTS,S/AS01 | E7: =C7&D7 -> 2026RTS,S/AS01 | F7: 9.3 | G7: =1.18*F7 -> 10.974
C8: 2027 | D8: RTS,S/AS01 | E8: =C8&D8 -> 2027RTS,S/AS01 | F8: 9.3 | G8: =1.18*F8 -> 10.974
C9: 2028 | D9: RTS,S/AS01 | E9: =C9&D9 -> 2028RTS,S/AS01 | F9: 5 | G9: 5
C10: 2029 | D10: RTS,S/AS01 | E10: =C10&D10 -> 2029RTS,S/AS01 | F10: 5 | G10: 5
C11: 2030 | D11: RTS,S/AS01 | E11: =C11&D11 -> 2030RTS,S/AS01 | F11: 5 | G11: 5
C12: 2031 | D12: RTS,S/AS01 | E12: =C12&D12 -> 2031RTS,S/AS01 | F12: 5 | G12: 5
C13: 2032 | D13: RTS,S/AS01 | E13: =C13&D13 -> 2032RTS,S/AS01 | F13: 5 | G13: 5
C14: 2033 | D14: RTS,S/AS01 | E14: =C14&D14 -> 2033RTS,S/AS01 | F14: 5 | G14: 5
C15: 2034 | D15: RTS,S/AS01 | E15: =C15&D15 -> 2034RTS,S/AS01 | F15: 5 | G15: 5
C16: 2035 | D16: RTS,S/AS01 | E16: =C16&D16 -> 2035RTS,S/AS01 | F16: 5 | G16: 5
C18: Price Data - R21/Matrix-M
C19: Country | D19: Product | E19: Code | F19: Price (local currency)/Dose | G19: Price(USD$)/Dose
C20: 2024 | D20: R21/Matrix-M | E20: =C20&D20 -> 2024R21/Matrix-M | F20: 3.9 | G20: 3.9
C21: 2025 | D21: R21/Matrix-M | E21: =C21&D21 -> 2025R21/Matrix-M | F21: 3.9 | G21: 3.9
C22: 2026 | D22: R21/Matrix-M | E22: =C22&D22 -> 2026R21/Matrix-M | F22: 3.9 | G22: 3.9
C23: 2027 | D23: R21/Matrix-M | E23: =C23&D23 -> 2027R21/Matrix-M | F23: 2.99 | G23: 2.99
C24: 2028 | D24: R21/Matrix-M | E24: =C24&D24 -> 2028R21/Matrix-M | F24: 2.99 | G24: 2.99
C25: 2029 | D25: R21/Matrix-M | E25: =C25&D25 -> 2029R21/Matrix-M | F25: 2.99 | G25: 2.99
C26: 2030 | D26: R21/Matrix-M | E26: =C26&D26 -> 2030R21/Matrix-M | F26: 2.99 | G26: 2.99
C27: 2031 | D27: R21/Matrix-M | E27: =C27&D27 -> 2031R21/Matrix-M | F27: 2.99 | G27: 2.99
C28: 2032 | D28: R21/Matrix-M | E28: =C28&D28 -> 2032R21/Matrix-M | F28: 2.99 | G28: 2.99
C29: 2033 | D29: R21/Matrix-M | E29: =C29&D29 -> 2033R21/Matrix-M | F29: 2.99 | G29: 2.99
C30: 2034 | D30: R21/Matrix-M | E30: =C30&D30 -> 2034R21/Matrix-M | F30: 2.99 | G30: 2.99
C31: 2035 | D31: R21/Matrix-M | E31: =C31&D31 -> 2035R21/Matrix-M | F31: 2.99 | G31: 2.99
B33: Source | C33: https://www.unicef.org/supply/media/24456/file/Malaria-vaccine-prices-11112025.pdf
C34: Price Data - R21/Matrix-M | I34: Row Labels | J34: Sum of Total Required Supply
C35: Country | D35: Product | E35: Code | F35: Price (local currency)/Dose | G35: Price(USD$)/Dose | I35: 2024 | J35: 5891273.1
C36: 2024 | D36: TBD | E36: =C36&D36 -> 2024TBD | G36: =(J36*G20+K36*G5)/(J36+K36) -> 3.9 | I36: 2025 | J36: 24440898
C37: 2025 | D37: TBD | E37: =C37&D37 -> 2025TBD | G37: =(J37*G21+K37*G6)/(J37+K37) -> 3.9 | I37: 2026 | J37: 53708547
C38: 2026 | D38: TBD | E38: =C38&D38 -> 2026TBD | G38: =(J38*G22+K38*G7)/(J38+K38) -> 3.9 | I38: 2027 | J38: 57796934
C39: 2027 | D39: TBD | E39: =C39&D39 -> 2027TBD | G39: =(J39*G23+K39*G8)/(J39+K39) -> 2.99 | I39: 2028 | J39: 60054164
C40: 2028 | D40: TBD | E40: =C40&D40 -> 2028TBD | G40: =(J40*G24+K40*G9)/(J40+K40) -> 2.99 | I40: 2029 | J40: 61825642
C41: 2029 | D41: TBD | E41: =C41&D41 -> 2029TBD | G41: =(J41*G25+K41*G10)/(J41+K41) -> 2.99 | I41: 2030 | J41: 63041071
C42: 2030 | D42: TBD | E42: =C42&D42 -> 2030TBD | G42: =(J42*G26+K42*G11)/(J42+K42) -> 2.99 | I42: 2031 | J42: 64395421
C43: 2031 | D43: TBD | E43: =C43&D43 -> 2031TBD | G43: =(J43*G27+K43*G12)/(J43+K43) -> 2.99 | I43: 2032 | J43: 65700509
C44: 2032 | D44: TBD | E44: =C44&D44 -> 2032TBD | G44: =(J44*G28+K44*G13)/(J44+K44) -> 2.99 | I44: 2033 | J44: 66970373
...
