Workbook

Sheet Summary
A1: Impact metric | B1: Immediate roll-out | C1: Six-month roll-out | D1: Waning efficacy | E1: Six-month roll-out + waning efficacy
A2: Cumulative cases averted so far | B2: =Summary[[#TOTALS],[Total cases averted so far (immediate roll-out)]] -> 182661.96 | C2: =Summary[[#TOTALS],[Total cases averted so far (six-month roll-out)]] -> 124515.61 | D2: =Summary[[#TOTALS],[Total cases averted so far (waning efficacy)]] -> 180580.63 | E2: =Summary[[#TOTALS],[Total cases averted so far (six-month roll-out, waning efficacy)]] -> 466871.3
A3: Cumulative lives saved so far | B3: =Summary[[#TOTALS],[Total lives saved so far (immediate roll-out)]] -> 1472324.4 | C3: =Summary[[#TOTALS],[Total lives saved so far (six-month roll-out)]] -> 993520.58 | D3: =Summary[[#TOTALS],[Total lives saved so far (waning efficacy)]] -> 1446310.9 | E3: =Summary[[#TOTALS],[Total lives saved so far (six-month roll-out, waning efficacy)]] -> 978.67686
A5: New cases averted per year | B5: =IFERROR(__xludf.DUMMYFUNCTION("SUM( FILTER( 'Shipments by country'!H2:H1001 * ( INDEX(Countries!S2:S1001, MATCH('Shipments by country'!B2:B1001, Countries!A2:A1001, 0) ) / 1000000 ) * INDEX('Vaccine efficacy curves'!C$2:C1001, MATCH('Shipments by country'!C2:C1001, 'Vaccine e"&"fficacy curves'!A$2:A1001, 0) ), ('Shipments by country'!E2:E1001 < NOW()) * ('Shipments by country'!I2:I1001 > 0) ) ) "),2292774.6125103454) -> 2292774.6 | C5: =IFERROR(__xludf.DUMMYFUNCTION("SUM( FILTER( 'Shipments by country'!H2:H1001 * ( INDEX(Countries!S2:S1001, MATCH('Shipments by country'!B2:B1001, Countries!A2:A1001, 0) ) / 1000000 ) * INDEX('Vaccine efficacy curves'!C$2:C1001, MATCH('Shipments by country'!C2:C1001, 'Vaccine e"&"fficacy curves'!A$2:A1001, 0) ), ('Shipments by country'!E2:E1001 < NOW()) * ('Shipments by country'!I2:I1001 > 0.25) ) ) "),1993636.7970195666) -> 1993636.8 | D5: =IFERROR(__xludf.DUMMYFUNCTION("SUM( FILTER( 'Shipments by country'!H2:H1001 * ( INDEX(Countries!S2:S1001, MATCH('Shipments by country'!B2:B1001, Countries!A2:A1001, 0))/1000000 ) * 'Shipments by country'!J2:J1001, ('Shipments by country'!E2:E1001 < NOW()) * ('Shipments by country'!I2:I"&"1001 > 0) ) )"),2747634.823742303) -> 2747634.8 | E5: =IFERROR(__xludf.DUMMYFUNCTION("SUM( FILTER( 'Shipments by country'!H2:H1001 * ( INDEX(Countries!S2:S1001, MATCH('Shipments by country'!B2:B1001, Countries!A2:A1001, 0))/1000000 ) * 'Shipments by country'!J2:J1001, ('Shipments by country'!E2:E1001 < NOW()) * ('Shipments by country'!I2:I"&"1001 > 0.25) ) )"),2371580.3980284315) -> 2371580.4
A6: New cases averted per day | B6: =B5/365.25 -> 6277.2748 | C6: =C5/365.25 -> 5458.2801 | D6: =D5/365.25 -> 7522.6142 | E6: =E5/365.25 -> 6493.0333
A7: New cases averted per hour | B7: =B6/24 -> 261.55312 | C7: =C6/24 -> 227.42834 | D7: =D6/24 -> 313.44226 | E7: =E6/24 -> 270.54305
A8: New cases averted per minute | B8: =B7/60 -> 4.3592186 | C8: =C7/60 -> 3.7904723 | D8: =D7/60 -> 5.2240376 | E8: =E7/60 -> 4.5090509
A10: New lives saved per year | B10: =IFERROR(__xludf.DUMMYFUNCTION("SUM( FILTER( 'Shipments by country'!H2:H1001 * ( INDEX(Countries!T2:T1001, MATCH('Shipments by country'!B2:B1001, Countries!A2:A1001, 0) ) / 1000000 ) * INDEX('Vaccine efficacy curves'!C$2:C1001, MATCH('Shipments by country'!C2:C1001, 'Vaccine e"&"fficacy curves'!A$2:A1001, 0) ), ('Shipments by country'!E2:E1001 < NOW()) * ('Shipments by country'!I2:I1001 > 0) ) ) "),4548.166149970364) -> 4548.1662 | C10: =IFERROR(__xludf.DUMMYFUNCTION("SUM( FILTER( 'Shipments by country'!H2:H1001 * ( INDEX(Countries!T2:T1001, MATCH('Shipments by country'!B2:B1001, Countries!A2:A1001, 0) ) / 1000000 ) * INDEX('Vaccine efficacy curves'!C$2:C1001, MATCH('Shipments by country'!C2:C1001, 'Vaccine e"&"fficacy curves'!A$2:A1001, 0) ), ('Shipments by country'!E2:E1001 < NOW()) * ('Shipments by country'!I2:I1001 > 0.25) ) ) "),3954.767880830597) -> 3954.7679 | D10: =IFERROR(__xludf.DUMMYFUNCTION("SUM( FILTER( 'Shipments by country'!H2:H1001 * ( INDEX(Countries!T2:T1001, MATCH('Shipments by country'!B2:B1001, Countries!A2:A1001, 0))/1000000 ) * 'Shipments by country'!J2:J1001, ('Shipments by country'!E2:E1001 < NOW()) * ('Shipments by country'!I2:I"&"1001 > 0) ) )"),5450.4701987004155) -> 5450.4702 | E10: =IFERROR(__xludf.DUMMYFUNCTION("SUM( FILTER( 'Shipments by country'!H2:H1001 * ( INDEX(Countries!T2:T1001, MATCH('Shipments by country'!B2:B1001, Countries!A2:A1001, 0))/1000000 ) * 'Shipments by country'!J2:J1001, ('Shipments by country'!E2:E1001 < NOW()) * ('Shipments by country'!I2:I"&"1001 > 0.25) ) )"),4704.492813812281) -> 4704.4928
A11: New lives saved per day | B11: =B10/365.25 -> 12.4522 | C11: =C10/365.25 -> 10.827564 | D11: =D10/365.25 -> 14.922574 | E11: =E10/365.25 -> 12.880199
A13: Cumulative cases expected without vaccines | B13: =MAX( 'Shipments by country'!I2:I1001 ) * SUMPRODUCT( Countries!J2:J1001, Countries!S2:S1001 ) /1000000 -> 4.9560935e+08 | C13: =MAX( 'Shipments by country'!I2:I1001 ) * SUMPRODUCT( Countries!J2:J1001, Countries!S2:S1001 ) /1000000 -> 4.9560935e+08 | D13: =MAX( 'Shipments by country'!I2:I1001 ) * SUMPRODUCT( Countries!J2:J1001, Countries!S2:S1001 ) /1000000 -> 4.9560935e+08 | E13: =MAX( 'Shipments by country'!I2:I1001 ) * SUMPRODUCT( Countries!J2:J1001, Countries!S2:S1001 ) /1000000 -> 4.9560935e+08
A14: Cumulative deaths expected without vaccines | B14: =MAX( 'Shipments by country'!I2:I1001 ) * SUMPRODUCT( Countries!J2:J1001, Countries!T2:T1001 ) /1000000 -> 1144503.1 | C14: =MAX( 'Shipments by country'!I2:I1001 ) * SUMPRODUCT( Countries!J2:J1001, Countries!T2:T1001 ) /1000000 -> 1144503.1 | D14: =MAX( 'Shipments by country'!I2:I1001 ) * SUMPRODUCT( Countries!J2:J1001, Countries!T2:T1001 ) /1000000 -> 1144503.1 | E14: =MAX( 'Shipments by country'!I2:I1001 ) * SUMPRODUCT( Countries!J2:J1001, Countries!T2:T1001 ) /1000000 -> 1144503.1
A16: Fraction of total malaria cases averted by vaccines | B16: =B2/B13 -> 0.00036856036 | C16: =C2/C13 -> 0.0002512374 | D16: =D2/D13 -> 0.00036436081 | E16: =E2/E13 -> 0.00094201472
A17: Fraction of total malaria deaths averted by vaccines | B17: =B3/B14 -> 1.2864312 | C17: =C3/C14 -> 0.86808031 | D17: =D3/D14 -> 1.2637021 | E17: =E3/E14 -> 0.00085511073

Sheet Countries
A1: Country | B1: RTS,S doses delivered | C1: R21 doses delivered | D1: RTS,S + R21 doses delivered | E1: Total RTS,S doses allocated | F1: Total R21 doses allocated | G1: Total RTS,S + R21 doses allocated | H1: Gavi income group | I1: PMI funding, USD (2023) | J1: Population at risk (2023) | K1: Population under five (2023) | L1: Eligible population (2023, 6-60 months) | M1: Eligible population covered | N1: Fraction of eligible population covered (6-60 months) | O1: Eligible population not covered (6-60 months) | P1: Fraction of eligible population not covered (6-60 months) | Q1: Total malaria cases per year (2023) | R1: Total malaria deaths per year (2023) | S1: Malaria cases per million at risk per year | T1: Malaria deaths per million at risk per year | U1: New cases averted per year (immediate roll-out) | V1: Total cases averted so far (immediate roll-out) | W1: New lives saved per year (immediate roll-out) | X1: Total lives saved so far (immediate roll-out) | Y1: New cases averted per year (six-month roll-out) | Z1: Total cases averted so far (six-month roll-out) | AA1: New lives saved per year (six-month roll-out) | AB1: Total lives saved so far (six-month roll-out) | AC1: New cases averted per year (waning efficacy) | AD1: Total cases averted so far (waning efficacy) | AE1: New lives saved per year (waning efficacy) | AF1: Total lives saved so far (waning efficacy) | AG1: New cases averted per year (six-month roll-out, waning efficacy) | AH1: Total cases averted so far (six-month roll-out, waning efficacy) | AI1: New lives saved per year (six-month roll-out, waning efficacy) | AJ1: Total lives saved so far (six-month roll-out, waning efficacy) | AK1: Current stock of further doses required (6-60 months) | AL1: Cost of current stock of further doses required, R21 (6-60 months, USD) | AM1: Share of existing dose costs funded by Gavi | AN1: Years in co-financing phase (as of 2025) | AO1: Co-financing cost of current stock of further doses required, R21 (6-60 months, USD) | AP1: Average GNI per capita (2021-2023) | AQ1: Cost to avert one case, R21 | AR1: Cost to save one life, R21 | AS1: Births per year | AT1: Flow of new vaccines required per year | AU1: Cost of flow of new vaccines required per year | AV1: Eligible population (2023, 5-36 months) | AW1: Fraction of eligible population covered (5-36 months) | AX1: Eligible population not covered (5-36 months) | AY1: Fraction of eligible population not covered (5-36 months) | AZ1: Current stock of further doses required (5-36 months) | BA1: Cost of current stock of further doses required, R21 (5-36 months, USD) | BB1: Co-financing cost of current stock of further doses required, R21 (5-36 months, USD)
A2: Angola | B2: =SUMIFS('Shipments by country'!F:F, 'Shipments by country'!B:B, A2, 'Shipments by country'!C:C, "RTS,S", 'Shipments by country'!G:G, "Delivered") -> 0 | C2: =SUMIFS('Shipments by country'!F:F, 'Shipments by country'!B:B, A2, 'Shipments by country'!C:C, "R21", 'Shipments by country'!G:G, "Delivered") -> 0 | D2: =B2+C2 -> 0 | E2: =SUMIFS('Shipments by country'!F:F, 'Shipments by country'!B:B, A2, 'Shipments by country'!C:C, "RTS,S") -> 0 | F2: =SUMIFS('Shipments by country'!F:F, 'Shipments by country'!B:B, A2, 'Shipments by country'!C:C, "R21") -> 0 | G2: =E2+F2 -> 0 | H2: Fully self-financing | I2: 19000000 | J2: 36749906 | K2: 6219256 | L2: =K2*0.9 -> 5597330.4 | M2: =G2/4 -> 0 | N2: =M2/L2 -> 0 | O2: =L2-M2 -> 5597330.4 | P2: =1-N2 -> 1 | Q2: 8251449 | R2: 16169 | S2: =Q2*1000000/J2 -> 224529.8 | T2: =R2*1000000/J2 -> 439.97391 | U2: =IFERROR(__xludf.DUMMYFUNCTION("IFERROR( SUM( FILTER( 'Shipments by country'!$H$2:$H1023 * ( INDEX(Countries!$S$2:$S1023, MATCH('Shipments by country'!$B$2:$B1023, Countries!$A$2:$A1023, 0) ) / 1000000 ) * INDEX('Vaccine efficacy curves'!$C$2:$C1023, MATCH('Shipments by country'!$C$2:$C"&"1023, 'Vaccine efficacy curves'!$A$2:$A1023, 0) ), ('Shipments by country'!$E$2:$E1023 < NOW()) * ('Shipments by country'!$I$2:$I1023 > 0) * ('Shipments by country'!$B$2:$B1023 = $A2) ) ), 0 )"),0.0) -> 0 | V2: =SUMIF('Shipments by country'!$B:$B,$A2,'Shipments by country'!$K:$K) -> 0 | W2: =IFERROR(__xludf.DUMMYFUNCTION("IFERROR( SUM( FILTER( 'Shipments by country'!$H$2:$H1023 * ( INDEX(Countries!$T$2:$T1023, MATCH('Shipments by country'!$B$2:$B1023, Countries!$A$2:$A1023, 0) ) / 1000000 ) * INDEX('Vaccine efficacy curves'!$C$2:$C1023, MATCH('Shipments by country'!$C$2:$C"&"1023, 'Vaccine efficacy curves'!$A$2:$A1023, 0) ), ('Shipments by country'!$E$2:$E1023 < NOW()) * ('Shipments by country'!$I$2:$I1023 > 0) * ('Shipments by country'!$B$2:$B1023 = $A2) ) ), 0 )"),0.0) -> 0 | X2: =SUMIF('Shipments by country'!$B:$B,$A2,'Shipments by country'!$L:$L) -> 0 | Y2: =IFERROR(__xludf.DUMMYFUNCTION("IFERROR( SUM( FILTER( 'Shipments by country'!$H$2:$H1023 * ( INDEX(Countries!$S$2:$S1023, MATCH('Shipments by country'!$B$2:$B1023, Countries!$A$2:$A1023, 0) ) / 1000000 ) * INDEX('Vaccine efficacy curves'!$C$2:$C1023, MATCH('Shipments by country'!$C$2:$C"&"1023, 'Vaccine efficacy curves'!$A$2:$A1023, 0) ), ('Shipments by country'!$E$2:$E1023 < NOW()) * ('Shipments by country'!$I$2:$I1023 > 0.25) * ('Shipments by country'!$B$2:$B1023 = $A2) ) ), 0 )"),0.0) -> 0 | Z2: =SUMIF('Shipments by country'!$B:$B,$A2,'Shipments by country'!$M:$M) -> 0 | AA2: =IFERROR(__xludf.DUMMYFUNCTION("IFERROR( SUM( FILTER( 'Shipments by country'!$H$2:$H1023 * ( INDEX(Countries!$T$2:$T1023, MATCH('Shipments by country'!$B$2:$B1023, Countries!$A$2:$A1023, 0) ) / 1000000 ) * INDEX('Vaccine efficacy curves'!$C$2:$C1023, MATCH('Shipments by country'!$C$2:$C"&"1023, 'Vaccine efficacy curves'!$A$2:$A1023, 0) ), ('Shipments by country'!$E$2:$E1023 < NOW()) * ('Shipments by country'!$I$2:$I1023 > 0.25) * ('Shipments by country'!$B$2:$B1023 = $A2) ) ), 0 )"),0.0) -> 0 | AB2: =SUMIF('Shipments by country'!$B:$B,$A2,'Shipments by country'!$N:$N) -> 0 | AC2: =IFERROR(__xludf.DUMMYFUNCTION("IFERROR( SUM( FILTER( 'Shipments by country'!$H$2:$H1023 * ( INDEX(Countries!$S$2:$S1023, MATCH('Shipments by country'!$B$2:$B1023, Countries!$A$2:$A1023, 0) ) / 1000000 ) * 'Shipments by country'!$J$2:$J1023, ('Shipments by country'!$E$2:$E1023 < NOW()) "&"* ('Shipments by country'!$I$2:$I1023 > 0) * ('Shipments by country'!$B$2:$B1023 = $A2) ) ), 0 )"),0.0) -> 0 | AD2: =SUMIF('Shipments by country'!$B:$B,$A2,'Shipments by country'!$O:$O) -> 0 | AE2: =IFERROR(__xludf.DUMMYFUNCTION("IFERROR( SUM( FILTER( 'Shipments by country'!$H$2:$H1023 * ( INDEX(Countries!$T$2:$T1023, MATCH('Shipments by country'!$B$2:$B1023, Countries!$A$2:$A1023, 0) ) / 1000000 ) * 'Shipments by country'!$J$2:$J1023, ('Shipments by country'!$E$2:$E1023 < NOW()) "&"* ('Shipments by country'!$I$2:$I1023 > 0) * ('Shipments by country'!$B$2:$B1023 = $A2) ) ), 0 )"),0.0) -> 0 | AF2: =SUMIF('Shipments by country'!$B:$B,$A2,'Shipments by country'!$P:$P) -> 0 | AG2: =IFERROR(__xludf.DUMMYFUNCTION("IFERROR( SUM( FILTER( 'Shipments by country'!$H$2:$H1023 * INDEX(Countries!$S$2:$S1023, MATCH('Shipments by country'!$B$2:$B1023, Countries!$A$2:$A1023, 0) ) / 1000000 "&" * 'Shipments by country'!$J$2:$J1023, ( 'Shipments by country'!$E$2:$E1023 < NOW() ) * ( 'Shipments by country'!$I$2:$I1023 > 0.25 ) * ( 'Shipments by country'!$"&"B$2:$B1023 = $A2 ) ) ), 0 ) "),0.0) -> 0 | AH2: =SUMIF('Shipments by country'!$B:$B,$A2,'Shipments by country'!$Q:$Q) -> 0 | AI2: =IFERROR(__xludf.DUMMYFUNCTION("IFERROR( SUM( FILTER( 'Shipments by country'!$H$2:$H1023 * ( INDEX(Countries!$T$2:$T1023, MATCH('Shipments by country'!$B$2:$B1023, Countries!$A$2:$A1023, 0) ) / 1000000 ) * 'Shipments by country"&"'!$J$2:$J1023, ('Shipments by country'!$E$2:$E1023 < NOW()) * ('Shipments by country'!$I$2:$I1023 > 0.25) * ('Shipments by country'!$B$2:$B1023 = $A2) ) ), 0 ) "),0.0) -> 0 | AJ2: =SUMIF('Shipments by country'!$B:$B,$A2,'Shipments by country'!$R:$R) -> 0 | AK2: =O2*4 -> 22389322 | AL2: =AK2*'Vaccine pricing'!B3 -> 66944072 | AM2: =IF($A2="","", LET( ctry,$A2, ctryCol,'Shipments by country'!$B$2:$B1023, vaccCol,'Shipments by country'!$C$2:$C1023, finCol,'Shipments by country'!$D$2:$D1023, doseCol,'Shipments by country'!$F$2:$F1023, price,IFERROR(VLOOKUP(vaccCol,'Vaccine pricing'!$A$2:$B1023,2,FALSE),0), totCost,SUMPRODUCT((ctryCol=ctry)*doseCol*price), gaviCost,SUMPRODUCT((ctryCol=ctry)*(finCol="Gavi")*doseCol*price), IF(totCost=0,"",gaviCost/totCost) )) | AN2: 8 | AO2: {=IF(AK2:AK46="","",IFS( H2:H46="Initial self-financing",AK2:AK46*0.2, H2:H46="Preparatory transition",AK2:AK46*0.2*POWER(1.15,N(AN2:AN46)-1), H2:H46="Accelerated transition",AK2:AK46*IF(N(AN2:AN46)<9,0.2+0.1*(N(AN2:AN46)-1),1)*'Vaccine pricing'!$B$3, H2:H46="Fully self-financing",AK2:AK46*'Vaccine pricing'!$B$3, TRUE,""))} -> 66944072 | AP2: 1933 | AQ2: ='Vaccine pricing'!$B$3*4/((S2/1000000)*'Vaccine efficacy curves'!$C$3) -> 71.022496 | AR2: ='Vaccine pricing'!$B$3*4/((T2/1000000)*'Vaccine efficacy curves'!$C$3) -> 36244.573 | AS2: =K2/5 -> 1243851.2 | AT2: =AS2*4 -> 4975404.8 | AU2: =AT2*'Vaccine pricing'!B3 -> 14876460 | AV2: =K2*31/60 -> 3213282.3 | AW2: =M2/AV2 -> 0 | AX2: =AV2-M2 -> 3213282.3 | AY2: =1-AW2 -> 1 | AZ2: =AX2*4 -> 12853129 | BA2: =AZ2*'Vaccine pricing'!B3 -> 38430856 | BB2: {=IF(AZ2:AZ46="","",IFS( H2:H46="Initial self-financing",AZ2:AZ46*0.2, H2:H46="Preparatory transition",AZ2:AZ46*0.2*POWER(1.15,N(AN2:AN46)-1), H2:H46="Accelerated transition",AZ2:AZ46*IF(N(AN2:AN46)<9,0.2+0.1*(N(AN2:AN46)-1),1)*'Vaccine pricing'!$B$3, H2:H46="Fully self-financing",AZ2:AZ46*'Vaccine pricing'!$B$3, TRUE,""))} -> 38430856
A3: Benin | B3: =SUMIFS('Shipments by country'!F:F, 'Shipments by country'!B:B, A3, 'Shipments by country'!C:C, "RTS,S", 'Shipments by country'!G:G, "Delivered") -> 976600 | C3: =SUMIFS('Shipments by country'!F:F, 'Shipments by country'!B:B, A3, 'Shipments by country'!C:C, "R21", 'Shipments by country'!G:G, "Delivered") -> 0 | D3: =B3+C3 -> 976600 | E3: =SUMIFS('Shipments by country'!F:F, 'Shipments by country'!B:B, A3, 'Shipments by country'!C:C, "RTS,S") -> 1211800 | F3: =SUMIFS('Shipments by country'!F:F, 'Shipments by country'!B:B, A3, 'Shipments by country'!C:C, "R21") -> 0 | G3: =E3+F3 -> 1211800 | H3: Preparatory transition | I3: 17000000 | J3: 14111034 | K3: 2176442 | L3: =K3*0.9 -> 1958797.8 | M3: =G3/4 -> 302950 | N3: =M3/L3 -> 0.15466119 | O3: =L3-M3 -> 1655847.8 | P3: =1-N3 -> 0.84533881 | Q3: 5127891 | R3: 9928 | S3: =Q3*1000000/J3 -> 363395.84 | T3: =R3*1000000/J3 -> 703.5629 | U3: =IFERROR(__xludf.DUMMYFUNCTION("IFERROR( SUM( FILTER( 'Shipments by country'!$H$2:$H1023 * ( INDEX(Countries!$S$2:$S1023, MATCH('Shipments by country'!$B$2:$B1023, Countries!$A$2:$A1023, 0) ) / 1000000 ) * INDEX('Vaccine efficacy curves'!$C$2:$C1023, MATCH('Shipments by country'!$C$2:$C"&"1023, 'Vaccine efficacy curves'!$A$2:$A1023, 0) ), ('Shipments by country'!$E$2:$E1023 < NOW()) * ('Shipments by country'!$I$2:$I1023 > 0) * ('Shipments by country'!$B$2:$B1023 = $A3) ) ), 0 )"),59970.08980109943) -> 59970.09 | V3: =SUMIF('Shipments by country'!$B:$B,$A3,'Shipments by country'!$K:$K) -> 1677.295 | W3: =IFERROR(__xludf.DUMMYFUNCTION("IFERROR( SUM( FILTER( 'Shipments by country'!$H$2:$H1023 * ( INDEX(Countries!$T$2:$T1023, MATCH('Shipments by country'!$B$2:$B1023, Countries!$A$2:$A1023, 0) ) / 1000000 ) * INDEX('Vaccine efficacy curves'!$C$2:$C1023, MATCH('Shipments by country'!$C$2:$C"&"1023, 'Vaccine efficacy curves'!$A$2:$A1023, 0) ), ('Shipments by country'!$E$2:$E1023 < NOW()) * ('Shipments by country'!$I$2:$I1023 > 0) * ('Shipments by country'!$B$2:$B1023 = $A3) ) ), 0 )"),118.9623833741803) -> 118.96238 | X3: =SUMIF('Shipments by country'!$B:$B,$A3,'Shipments by country'!$L:$L) -> 61394.239 | Y3: =IFERROR(__xludf.DUMMYFUNCTION("IFERROR( SUM( FILTER( 'Shipments by country'!$H$2:$H1023 * ( INDEX(Countries!$S$2:$S1023, MATCH('Shipments by country'!$B$2:$B1023, Countries!$A$2:$A1023, 0) ) / 1000000 ) * INDEX('Vaccine efficacy curves'!$C$2:$C1023, MATCH('Shipments by country'!$C$2:$C"&"1023, 'Vaccine efficacy curves'!$A$2:$A1023, 0) ), ('Shipments by country'!$E$2:$E1023 < NOW()) * ('Shipments by country'!$I$2:$I1023 > 0.25) * ('Shipments by country'!$B$2:$B1023 = $A3) ) ), 0 )"),59321.79125645971) -> 59321.791 | Z3: =SUMIF('Shipments by country'!$B:$B,$A3,'Shipments by country'!$M:$M) -> 1258.5538 | AA3: =IFERROR(__xludf.DUMMYFUNCTION("IFERROR( SUM( FILTER( 'Shipments by country'!$H$2:$H1023 * ( INDEX(Countries!$T$2:$T1023, MATCH('Shipments by country'!$B$2:$B1023, Countries!$A$2:$A1023, 0) ) / 1000000 ) * INDEX('Vaccine efficacy curves'!$C$2:$C1023, MATCH('Shipments by country'!$C$2:$C"&"1023, 'Vaccine efficacy curves'!$A$2:$A1023, 0) ), ('Shipments by country'!$E$2:$E1023 < NOW()) * ('Shipments by country'!$I$2:$I1023 > 0.25) * ('Shipments by country'!$B$2:$B1023 = $A3) ) ), 0 )"),117.67635661877368) -> 117.67636 | AB3: =SUMIF('Shipments by country'!$B:$B,$A3,'Shipments by country'!$N:$N) -> 46067.004 | AC3: =IFERROR(__xludf.DUMMYFUNCTION("IFERROR( SUM( FILTER( 'Shipments by country'!$H$2:$H1023 * ( INDEX(Countries!$S$2:$S1023, MATCH('Shipments by country'!$B$2:$B1023, Countries!$A$2:$A1023, 0) ) / 1000000 ) * 'Shipments by country'!$J$2:$J1023, ('Shipments by country'!$E$2:$E1023 < NOW()) "&"* ('Shipments by country'!$I$2:$I1023 > 0) * ('Shipments by country'!$B$2:$B1023 = $A3) ) ), 0 )"),58204.04753329213) -> 58204.048 | AD3: =SUMIF('Shipments by country'!$B:$B,$A3,'Shipments by country'!$O:$O) -> 1635.9611 | AE3: =IFERROR(__xludf.DUMMYFUNCTION("IFERROR( SUM( FILTER( 'Shipments by country'!$H$2:$H1023 * ( INDEX(Countries!$T$2:$T1023, MATCH('Shipments by country'!$B$2:$B1023, Countries!$A$2:$A1023, 0) ) / 1000000 ) * 'Shipments by country'!$J$2:$J1023, ('Shipments by country'!$E$2:$E1023 < NOW()) "&"* ('Shipments by country'!$I$2:$I1023 > 0) * ('Shipments by country'!$B$2:$B1023 = $A3) ) ), 0 )"),115.45909368402467) -> 115.45909 | AF3: =SUMIF('Shipments by country'!$B:$B,$A3,'Shipments by country'!$P:$P) -> 59881.29 | AG3: =IFERROR(__xludf.DUMMYFUNCTION("IFERROR( SUM( FILTER( 'Shipments by country'!$H$2:$H1023 * INDEX(Countries!$S$2:$S1023, MATCH('Shipments by country'!$B$2:$B1023, Countries!$A$2:$A1023, 0) ) / 1000000 "&" * 'Shipments by country'!$J$2:$J1023, ( 'Shipments by country'!$E$2:$E1023 < NOW() ) * ( 'Shipments by country'!$I$2:$I1023 > 0.25 ) * ( 'Shipments by country'!$"&"B$2:$B1023 = $A3 ) ) ), 0 ) "),57555.74898865242) -> 57555.749 | AH3: =SUMIF('Shipments by country'!$B:$B,$A3,'Shipments by country'!$Q:$Q) -> 14735.416 | AI3: =IFERROR(__xludf.DUMMYFUNCTION("IFERROR( SUM( FILTER( 'Shipments by country'!$H$2:$H1023 * ( INDEX(Countries!$T$2:$T1023, MATCH('Shipments by country'!$B$2:$B1023, Countries!$A$2:$A1023, 0) ) / 1000000 ) * 'Shipments by country"&"'!$J$2:$J1023, ('Shipments by country'!$E$2:$E1023 < NOW()) * ('Shipments by country'!$I$2:$I1023 > 0.25) * ('Shipments by country'!$B$2:$B1023 = $A3) ) ), 0 ) "),114.17306692861804) -> 114.17307 | AJ3: =SUMIF('Shipments by country'!$B:$B,$A3,'Shipments by country'!$R:$R) -> 28.528923 | AK3: =O3*4 -> 6623391.2 | AL3: =AK3*'Vaccine pricing'!B3 -> 19803940 | AM3: =IF($A3="","", LET( ctry,$A3, ctryCol,'Shipments by country'!$B$2:$B1023, vaccCol,'Shipments by country'!$C$2:$C1023, finCol,'Shipments by country'!$D$2:$D1023, doseCol,'Shipments by country'!$F$2:$F1023, price,IFERROR(VLOOKUP(vaccCol,'Vaccine pricing'!$A$2:$B1023,2,FALSE),0), totCost,SUMPRODUCT((ctryCol=ctry)*doseCol*price), gaviCost,SUMPRODUCT((ctryCol=ctry)*(finCol="Gavi")*doseCol*price), IF(totCost=0,"",gaviCost/totCost) )) -> 0.97062221 | AN3: 4 | AO3: 2014670 | AP3: 1403 | AQ3: ='Vaccine pricing'!$B$3*4/((S3/1000000)*'Vaccine efficacy curves'!$C$3) -> 43.882359 | AR3: ='Vaccine pricing'!$B$3*4/((T3/1000000)*'Vaccine efficacy curves'!$C$3) -> 22665.588 | AS3: =K3/5 -> 435288.4 | AT3: =AS3*4 -> 1741153.6 | AU3: =AT3*'Vaccine pricing'!B3 -> 5206049.3 | AV3: =K3*31/60 -> 1124495 | AW3: =M3/AV3 -> 0.26940982 | AX3: =AV3-M3 -> 821545.03 | AY3: =1-AW3 -> 0.73059018 | AZ3: =AX3*4 -> 3286180.1 | BA3: =AZ3*'Vaccine pricing'!B3 -> 9825678.6 | BB3: 999573.84
A4: Botswana | B4: =SUMIFS('Shipments by country'!F:F, 'Shipments by country'!B:B, A4, 'Shipments by country'!C:C, "RTS,S", 'Shipments by country'!G:G, "Delivered") -> 0 | C4: =SUMIFS('Shipments by country'!F:F, 'Shipments by country'!B:B, A4, 'Shipments by country'!C:C, "R21", 'Shipments by country'!G:G, "Delivered") -> 0 | D4: =B4+C4 -> 0 | E4: =SUMIFS('Shipments by country'!F:F, 'Shipments by country'!B:B, A4, 'Shipments by country'!C:C, "RTS,S") -> 0 | F4: =SUMIFS('Shipments by country'!F:F, 'Shipments by country'!B:B, A4, 'Shipments by country'!C:C, "R21") -> 0 | G4: =E4+F4 -> 0 | H4: N/A | I4: 0 | J4: 1644352 | K4: 293659 | L4: =K4*0.9 -> 264293.1 | M4: =G4/4 -> 0 | N4: =M4/L4 -> 0 | O4: =L4-M4 -> 264293.1 | P4: =1-N4 -> 1 | Q4: 778 | R4: 4 | S4: =Q4*1000000/J4 -> 473.13471 | T4: =R4*1000000/J4 -> 2.4325692 | U4: =IFERROR(__xludf.DUMMYFUNCTION("IFERROR( SUM( FILTER( 'Shipments by country'!$H$2:$H1023 * ( INDEX(Countries!$S$2:$S1023, MATCH('Shipments by country'!$B$2:$B1023, Countries!$A$2:$A1023, 0) ) / 1000000 ) * INDEX('Vaccine efficacy curves'!$C$2:$C1023, MATCH('Shipments by country'!$C$2:$C"&"1023, 'Vaccine efficacy curves'!$A$2:$A1023, 0) ), ('Shipments by country'!$E$2:$E1023 < NOW()) * ('Shipments by country'!$I$2:$I1023 > 0) * ('Shipments by country'!$B$2:$B1023 = $A4) ) ), 0 )"),0.0) -> 0 | V4: =SUMIF('Shipments by country'!$B:$B,$A4,'Shipments by country'!$K:$K) -> 0 | W4: =IFERROR(__xludf.DUMMYFUNCTION("IFERROR( SUM( FILTER( 'Shipments by country'!$H$2:$H1023 * ( INDEX(Countries!$T$2:$T1023, MATCH('Shipments by country'!$B$2:$B1023, Countries!$A$2:$A1023, 0) ) / 1000000 ) * INDEX('Vaccine efficacy curves'!$C$2:$C1023, MATCH('Shipments by country'!$C$2:$C"&"1023, 'Vaccine efficacy curves'!$A$2:$A1023, 0) ), ('Shipments by country'!$E$2:$E1023 < NOW()) * ('Shipments by country'!$I$2:$I1023 > 0) * ('Shipments by country'!$B$2:$B1023 = $A4) ) ), 0 )"),0.0) -> 0 | X4: =SUMIF('Shipments by country'!$B:$B,$A4,'Shipments by country'!$L:$L) -> 0 | Y4: =IFERROR(__xludf.DUMMYFUNCTION("IFERROR( SUM( FILTER( 'Shipments by country'!$H$2:$H1023 * ( INDEX(Countries!$S$2:$S1023, MATCH('Shipments by country'!$B$2:$B1023, Countries!$A$2:$A1023, 0) ) / 1000000 ) * INDEX('Vaccine efficacy curves'!$C$2:$C1023, MATCH('Shipments by country'!$C$2:$C"&"1023, 'Vaccine efficacy curves'!$A$2:$A1023, 0) ), ('Shipments by country'!$E$2:$E1023 < NOW()) * ('Shipments by country'!$I$2:$I1023 > 0.25) * ('Shipments by country'!$B$2:$B1023 = $A4) ) ), 0 )"),0.0) -> 0 | Z4: =SUMIF('Shipments by country'!$B:$B,$A4,'Shipments by country'!$M:$M) -> 0 | AA4: =IFERROR(__xludf.DUMMYFUNCTION("IFERROR( SUM( FILTER( 'Shipments by country'!$H$2:$H1023 * ( INDEX(Countries!$T$2:$T1023, MATCH('Shipments by country'!$B$2:$B1023, Countries!$A$2:$A1023, 0) ) / 1000000 ) * INDEX('Vaccine efficacy curves'!$C$2:$C1023, MATCH('Shipments by country'!$C$2:$C"&"1023, 'Vaccine efficacy curves'!$A$2:$A1023, 0) ), ('Shipments by country'!$E$2:$E1023 < NOW()) * ('Shipments by country'!$I$2:$I1023 > 0.25) * ('Shipments by country'!$B$2:$B1023 = $A4) ) ), 0 )"),0.0) -> 0 | AB4: =SUMIF('Shipments by country'!$B:$B,$A4,'Shipments by country'!$N:$N) -> 0 | AC4: =IFERROR(__xludf.DUMMYFUNCTION("IFERROR( SUM( FILTER( 'Shipments by country'!$H$2:$H1023 * ( INDEX(Countries!$S$2:$S1023, MATCH('Shipments by country'!$B$2:$B1023, Countries!$A$2:$A1023, 0) ) / 1000000 ) * 'Shipments by country'!$J$2:$J1023, ('Shipments by country'!$E$2:$E1023 < NOW()) "&"* ('Shipments by country'!$I$2:$I1023 > 0) * ('Shipments by country'!$B$2:$B1023 = $A4) ) ), 0 )"),0.0) -> 0 | AD4: =SUMIF('Shipments by country'!$B:$B,$A4,'Shipments by country'!$O:$O) -> 0 | AE4: =IFERROR(__xludf.DUMMYFUNCTION("IFERROR( SUM( FILTER( 'Shipments by country'!$H$2:$H1023 * ( INDEX(Countries!$T$2:$T1023, MATCH('Shipments by country'!$B$2:$B1023, Countries!$A$2:$A1023, 0) ) / 1000000 ) * 'Shipments by country'!$J$2:$J1023, ('Shipments by country'!$E$2:$E1023 < NOW()) "&"* ('Shipments by country'!$I$2:$I1023 > 0) * ('Shipments by country'!$B$2:$B1023 = $A4) ) ), 0 )"),0.0) -> 0 | AF4: =SUMIF('Shipments by country'!$B:$B,$A4,'Shipments by country'!$P:$P) -> 0 | AG4: =IFERROR(__xludf.DUMMYFUNCTION("IFERROR( SUM( FILTER( 'Shipments by country'!$H$2:$H1023 * INDEX(Countries!$S$2:$S1023, MATCH('Shipments by country'!$B$2:$B1023, Countries!$A$2:$A1023, 0) ) / 1000000 "&" * 'Shipments by country'!$J$2:$J1023, ( 'Shipments by country'!$E$2:$E1023 < NOW() ) * ( 'Shipments by country'!$I$2:$I1023 > 0.25 ) * ( 'Shipments by country'!$"&"B$2:$B1023 = $A4 ) ) ), 0 ) "),0.0) -> 0 | AH4: =SUMIF('Shipments by country'!$B:$B,$A4,'Shipments by country'!$Q:$Q) -> 0 | AI4: =IFERROR(__xludf.DUMMYFUNCTION("IFERROR( SUM( FILTER( 'Shipments by country'!$H$2:$H1023 * ( INDEX(Countries!$T$2:$T1023, MATCH('Shipments by country'!$B$2:$B1023, Countries!$A$2:$A1023, 0) ) / 1000000 ) * 'Shipments by country"&"'!$J$2:$J1023, ('Shipments by country'!$E$2:$E1023 < NOW()) * ('Shipments by country'!$I$2:$I1023 > 0.25) * ('Shipments by country'!$B$2:$B1023 = $A4) ) ), 0 ) "),0.0) -> 0 | AJ4: =SUMIF('Shipments by country'!$B:$B,$A4,'Shipments by country'!$R:$R) -> 0 | AK4: =O4*4 -> 1057172.4 | AL4: =AK4*'Vaccine pricing'!B3 -> 3160945.5 | AM4: =IF($A4="","", LET( ctry,$A4, ctryCol,'Shipments by country'!$B$2:$B1023, vaccCol,'Shipments by country'!$C$2:$C1023, finCol,'Shipments by country'!$D$2:$D1023, doseCol,'Shipments by country'!$F$2:$F1023, price,IFERROR(VLOOKUP(vaccCol,'Vaccine pricing'!$A$2:$B1023,2,FALSE),0), totCost,SUMPRODUCT((ctryCol=ctry)*doseCol*price), gaviCost,SUMPRODUCT((ctryCol=ctry)*(finCol="Gavi")*doseCol*price), IF(totCost=0,"",gaviCost/totCost) )) | AN4: - | AP4: - | AQ4: ='Vaccine pricing'!$B$3*4/((S4/1000000)*'Vaccine efficacy curves'!$C$3) -> 33704.284 | AR4: ='Vaccine pricing'!$B$3*4/((T4/1000000)*'Vaccine efficacy curves'!$C$3) -> 6555483.3 | AS4: =K4/5 -> 58731.8 | AT4: =AS4*4 -> 234927.2 | AU4: =AT4*'Vaccine pricing'!B3 -> 702432.33 | AV4: =K4*31/60 -> 151723.82 | AW4: =M4/AV4 -> 0 | AX4: =AV4-M4 -> 151723.82 | AY4: =1-AW4 -> 1 | AZ4: =AX4*4 -> 606895.27 | BA4: =AZ4*'Vaccine pricing'!B3 -> 1814616.8
A5: Burkina Faso | B5: =SUMIFS('Shipments by country'!F:F, 'Shipments by country'!B:B, A5, 'Shipments by country'!C:C, "RTS,S", 'Shipments by country'!G:G, "Delivered") -> 1374600 | C5: =SUMIFS('Shipments by country'!F:F, 'Shipments by country'!B:B, A5, 'Shipments by country'!C:C, "R21", 'Shipments by country'!G:G, "Delivered") -> 800000 | D5: =B5+C5 -> 2174600 | E5: =SUMIFS('Shipments by country'!F:F, 'Shipments by country'!B:B, A5, 'Shipments by country'!C:C, "RTS,S") -> 1374600 | F5: =SUMIFS('Shipments by country'!F:F, 'Shipments by country'!B:B, A5, 'Shipments by country'!C:C, "R21") -> 2209800 | G5: =E5+F5 -> 3584400 | H5: Initial self-financing | I5: 26000000 | J5: 23025776 | K5: 3351139 | L5: =K5*0.9 -> 3016025.1 | M5: =G5/4 -> 896100 | N5: =M5/L5 -> 0.29711291 | O5: =L5-M5 -> 2119925.1 | P5: =1-N5 -> 0.70288709 | Q5: 8139355 | R5: 16146 | S5: =Q5*1000000/J5 -> 353488.85 | T5: =R5*1000000/J5 -> 701.21415 | U5: =IFERROR(__xludf.DUMMYFUNCTION("IFERROR( SUM( FILTER( 'Shipments by country'!$H$2:$H1023 * ( INDEX(Countries!$S$2:$S1023, MATCH('Shipments by country'!$B$2:$B1023, Countries!$A$2:$A1023, 0) ) / 1000000 ) * INDEX('Vaccine efficacy curves'!$C$2:$C1023, MATCH('Shipments by country'!$C$2:$C"&"1023, 'Vaccine efficacy curves'!$A$2:$A1023, 0) ), ('Shipments by country'!$E$2:$E1023 < NOW()) * ('Shipments by country'!$I$2:$I1023 > 0) * ('Shipments by country'!$B$2:$B1023 = $A5) ) ), 0 )"),152558.00943212508) -> 152558.01 | V5: =SUMIF('Shipments by country'!$B:$B,$A5,'Shipments by country'!$K:$K) -> 5310.2456 | W5: =IFERROR(__xludf.DUMMYFUNCTION("IFERROR( SUM( FILTER( 'Shipments by country'!$H$2:$H1023 * ( INDEX(Countries!$T$2:$T1023, MATCH('Shipments by country'!$B$2:$B1023, Countries!$A$2:$A1023, 0) ) / 1000000 ) * INDEX('Vaccine efficacy curves'!$C$2:$C1023, MATCH('Shipments by country'!$C$2:$C"&"1023, 'Vaccine efficacy curves'!$A$2:$A1023, 0) ), ('Shipments by country'!$E$2:$E1023 < NOW()) * ('Shipments by country'!$I$2:$I1023 > 0) * ('Shipments by country'!$B$2:$B1023 = $A5) ) ), 0 )"),302.6286014421404) -> 302.6286 | X5: =SUMIF('Shipments by country'!$B:$B,$A5,'Shipments by country'!$L:$L) -> 116258.68 | Y5: =IFERROR(__xludf.DUMMYFUNCTION("IFERROR( SUM( FILTER( 'Shipments by country'!$H$2:$H1023 * ( INDEX(Countries!$S$2:$S1023, MATCH('Shipments by country'!$B$2:$B1023, Countries!$A$2:$A1023, 0) ) / 1000000 ) * INDEX('Vaccine efficacy curves'!$C$2:$C1023, MATCH('Shipments by country'!$C$2:$C"&"1023, 'Vaccine efficacy curves'!$A$2:$A1023, 0) ), ('Shipments by country'!$E$2:$E1023 < NOW()) * ('Shipments by country'!$I$2:$I1023 > 0.25) * ('Shipments by country'!$B$2:$B1023 = $A5) ) ), 0 )"),107617.55841019211) -> 107617.56 | Z5: =SUMIF('Shipments by country'!$B:$B,$A5,'Shipments by country'!$M:$M) -> 3621.0306 | AA5: =IFERROR(__xludf.DUMMYFUNCTION("IFERROR( SUM( FILTER( 'Shipments by country'!$H$2:$H1023 * ( INDEX(Countries!$T$2:$T1023, MATCH('Shipments by country'!$B$2:$B1023, Countries!$A$2:$A1023, 0) ) / 1000000 ) * INDEX('Vaccine efficacy curves'!$C$2:$C1023, MATCH('Shipments by country'!$C$2:$C"&"1023, 'Vaccine efficacy curves'!$A$2:$A1023, 0) ), ('Shipments by country'!$E$2:$E1023 < NOW()) * ('Shipments by country'!$I$2:$I1023 > 0.25) * ('Shipments by country'!$B$2:$B1023 = $A5) ) ), 0 )"),213.4804413975017) -> 213.48044 | AB5: =SUMIF('Shipments by country'!$B:$B,$A5,'Shipments by country'!$N:$N) -> 79276.226 | AC5: =IFERROR(__xludf.DUMMYFUNCTION("IFERROR( SUM( FILTER( 'Shipments by country'!$H$2:$H1023 * ( INDEX(Countries!$S$2:$S1023, MATCH('Shipments by country'!$B$2:$B1023, Countries!$A$2:$A1023, 0) ) / 1000000 ) * 'Shipments by country'!$J$2:$J1023, ('Shipments by country'!$E$2:$E1023 < NOW()) "&"* ('Shipments by country'!$I$2:$I1023 > 0) * ('Shipments by country'!$B$2:$B1023 = $A5) ) ), 0 )"),176361.47787601806) -> 176361.48 | AD5: =SUMIF('Shipments by country'!$B:$B,$A5,'Shipments by country'!$O:$O) -> 5124.6193 | AE5: =IFERROR(__xludf.DUMMYFUNCTION("IFERROR( SUM( FILTER( 'Shipments by country'!$H$2:$H1023 * ( INDEX(Countries!$T$2:$T1023, MATCH('Shipments by country'!$B$2:$B1023, Countries!$A$2:$A1023, 0) ) / 1000000 ) * 'Shipments by country'!$J$2:$J1023, ('Shipments by country'!$E$2:$E1023 < NOW()) "&"* ('Shipments by country'!$I$2:$I1023 > 0) * ('Shipments by country'!$B$2:$B1023 = $A5) ) ), 0 )"),349.8474291619162) -> 349.84743 | AF5: =SUMIF('Shipments by country'!$B:$B,$A5,'Shipments by country'!$P:$P) -> 112194.71 | AG5: =IFERROR(__xludf.DUMMYFUNCTION("IFERROR( SUM( FILTER( 'Shipments by country'!$H$2:$H1023 * INDEX(Countries!$S$2:$S1023, MATCH('Shipments by country'!$B$2:$B1023, Countries!$A$2:$A1023, 0) ) / 1000000 "&" * 'Shipments by country'!$J$2:$J1023, ( 'Shipments by country'!$E$2:$E1023 < NOW() ) * ( 'Shipments by country'!$I$2:$I1023 > 0.25 ) * ( 'Shipments by country'!$"&"B$2:$B1023 = $A5 ) ) ), 0 ) "),116173.37382878644) -> 116173.37 | AH5: =SUMIF('Shipments by country'!$B:$B,$A5,'Shipments by country'!$Q:$Q) -> 35818.456 | AI5: =IFERROR(__xludf.DUMMYFUNCTION("IFERROR( SUM( FILTER( 'Shipments by country'!$H$2:$H1023 * ( INDEX(Countries!$T$2:$T1023, MATCH('Shipments by country'!$B$2:$B1023, Countries!$A$2:$A1023, 0) ) / 1000000 ) * 'Shipments by country"&"'!$J$2:$J1023, ('Shipments by country'!$E$2:$E1023 < NOW()) * ('Shipments by country'!$I$2:$I1023 > 0.25) * ('Shipments by country'!$B$2:$B1023 = $A5) ) ), 0 ) "),230.4525719592751) -> 230.45257 | AJ5: =SUMIF('Shipments by country'!$B:$B,$A5,'Shipments by country'!$R:$R) -> 71.052902 | AK5: =O5*4 -> 8479700.4 | AL5: =AK5*'Vaccine pricing'!B3 -> 25354304 | AM5: =IF($A5="","", LET( ctry,$A5, ctryCol,'Shipments by country'!$B$2:$B1023, vaccCol,'Shipments by country'!$C$2:$C1023, finCol,'Shipments by country'!$D$2:$D1023, doseCol,'Shipments by country'!$F$2:$F1023, price,IFERROR(VLOOKUP(vaccCol,'Vaccine pricing'!$A$2:$B1023,2,FALSE),0), totCost,SUMPRODUCT((ctryCol=ctry)*doseCol*price), gaviCost,SUMPRODUCT((ctryCol=ctry)*(finCol="Gavi")*doseCol*price), IF(totCost=0,"",gaviCost/totCost) )) -> 0.9621415 | AN5: 11 | AO5: 1695940.1 | AP5: 850 | AQ5: ='Vaccine pricing'!$B$3*4/((S5/1000000)*'Vaccine efficacy curves'!$C$3) -> 45.11222 | AR5: ='Vaccine pricing'!$B$3*4/((T5/1000000)*'Vaccine efficacy curves'!$C$3) -> 22741.507 | AS5: =K5/5 -> 670227.8 | AT5: =AS5*4 -> 2680911.2 | AU5: =AT5*'Vaccine pricing'!B3 -> 8015924.5 | AV5: =K5*31/60 -> 1731421.8 | AW5: =M5/AV5 -> 0.51755152 | AX5: =AV5-M5 -> 835321.82 | AY5: =1-AW5 -> 0.48244848 | AZ5: =AX5*4 -> 3341287.3 | BA5: =AZ5*'Vaccine pricing'!B3 -> 9990448.9 | BB5: 668257.45
A6: Burundi | B6: =SUMIFS('Shipments by country'!F:F, 'Shipments by country'!B:B, A6, 'Shipments by country'!C:C, "RTS,S", 'Shipments by country'!G:G, "Delivered") -> 1426250 | C6: =SUMIFS('Shipments by country'!F:F, 'Shipments by country'!B:B, A6, 'Shipments by country'!C:C, "R21", 'Shipments by country'!G:G, "Delivered") -> 0 | D6: =B6+C6 -> 1426250 | E6: =SUMIFS('Shipments by country'!F:F, 'Shipments by country'!B:B, A6, 'Shipments by country'!C:C, "RTS,S") -> 1445550 | F6: =SUMIFS('Shipments by country'!F:F, 'Shipments by country'!B:B, A6, 'Shipments by country'!C:C, "R21") -> 0 | G6: =E6+F6 -> 1445550 | H6: Initial self-financing | I6: 15000000 | J6: 13689449 | K6: 2167233 | L6: =K6*0.9 -> 1950509.7 | M6: =G6/4 -> 361387.5 | N6: =M6/L6 -> 0.18527849 | O6: =L6-M6 -> 1589122.2 | P6: =1-N6 -> 0.81472151 | Q6: 3354726 | R6: 6302 | S6: =Q6*1000000/J6 -> 245059.24 | T6: =R6*1000000/J6 -> 460.35454 | U6: =IFERROR(__xludf.DUMMYFUNCTION("IFERROR( SUM( FILTER( 'Shipments by country'!$H$2:$H1023 * ( INDEX(Countries!$S$2:$S1023, MATCH('Shipments by country'!$B$2:$B1023, Countries!$A$2:$A1023, 0) ) / 1000000 ) * INDEX('Vaccine efficacy curves'!$C$2:$C1023, MATCH('Shipments by country'!$C$2:$C"&"1023, 'Vaccine efficacy curves'!$A$2:$A1023, 0) ), ('Shipments by country'!$E$2:$E1023 < NOW()) * ('Shipments by country'!$I$2:$I1023 > 0) * ('Shipments by country'!$B$2:$B1023 = $A6) ) ), 0 )"),71538.0123056439) -> 71538.012 | V6: =SUMIF('Shipments by country'!$B:$B,$A6,'Shipments by country'!$K:$K) -> 620.4038 | W6: =IFERROR(__xludf.DUMMYFUNCTION("IFERROR( SUM( FILTER( 'Shipments by country'!$H$2:$H1023 * ( INDEX(Countries!$T$2:$T1023, MATCH('Shipments by country'!$B$2:$B1023, Countries!$A$2:$A1023, 0) ) / 1000000 ) * INDEX('Vaccine efficacy curves'!$C$2:$C1023, MATCH('Shipments by country'!$C$2:$C"&"1023, 'Vaccine efficacy curves'!$A$2:$A1023, 0) ), ('Shipments by country'!$E$2:$E1023 < NOW()) * ('Shipments by country'!$I$2:$I1023 > 0) * ('Shipments by country'!$B$2:$B1023 = $A6) ) ), 0 )"),141.90961650977584) -> 141.90962 | X6: =SUMIF('Shipments by country'!$B:$B,$A6,'Shipments by country'!$L:$L) -> 24124.99 | Y6: =IFERROR(__xludf.DUMMYFUNCTION("IFERROR( SUM( FILTER( 'Shipments by country'!$H$2:$H1023 * ( INDEX(Countries!$S$2:$S1023, MATCH('Shipments by country'!$B$2:$B1023, Countries!$A$2:$A1023, 0) ) / 1000000 ) * INDEX('Vaccine efficacy curves'!$C$2:$C1023, MATCH('Shipments by country'!$C$2:$C"&"1023, 'Vaccine efficacy curves'!$A$2:$A1023, 0) ), ('Shipments by country'!$E$2:$E1023 < NOW()) * ('Shipments by country'!$I$2:$I1023 > 0.25) * ('Shipments by country'!$B$2:$B1023 = $A6) ) ), 0 )"),48748.58636620977) -> 48748.586 | Z6: =SUMIF('Shipments by country'!$B:$B,$A6,'Shipments by country'!$M:$M) -> 331.28419 | AA6: =IFERROR(__xludf.DUMMYFUNCTION("IFERROR( SUM( FILTER( 'Shipments by country'!$H$2:$H1023 * ( INDEX(Countries!$T$2:$T1023, MATCH('Shipments by country'!$B$2:$B1023, Countries!$A$2:$A1023, 0) ) / 1000000 ) * INDEX('Vaccine efficacy curves'!$C$2:$C1023, MATCH('Shipments by country'!$C$2:$C"&"1023, 'Vaccine efficacy curves'!$A$2:$A1023, 0) ), ('Shipments by country'!$E$2:$E1023 < NOW()) * ('Shipments by country'!$I$2:$I1023 > 0.25) * ('Shipments by country'!$B$2:$B1023 = $A6) ) ), 0 )"),96.70234010788607) -> 96.70234 | AB6: =SUMIF('Shipments by country'!$B:$B,$A6,'Shipments by country'!$N:$N) -> 12882.3 | AC6: =IFERROR(__xludf.DUMMYFUNCTION("IFERROR( SUM( FILTER( 'Shipments by country'!$H$2:$H1023 * ( INDEX(Countries!$S$2:$S1023, MATCH('Shipments by country'!$B$2:$B1023, Countries!$A$2:$A1023, 0) ) / 1000000 ) * 'Shipments by country'!$J$2:$J1023, ('Shipments by country'!$E$2:$E1023 < NOW()) "&"* ('Shipments by country'!$I$2:$I1023 > 0) * ('Shipments by country'!$B$2:$B1023 = $A6) ) ), 0 )"),71538.0123056439) -> 71538.012 | AD6: =SUMIF('Shipments by country'!$B:$B,$A6,'Shipments by country'!$O:$O) -> 620.4038 | AE6: =IFERROR(__xludf.DUMMYFUNCTION("IFERROR( SUM( FILTER( 'Shipments by country'!$H$2:$H1023 * ( INDEX(Countries!$T$2:$T1023, MATCH('Shipments by country'!$B$2:$B1023, Countries!$A$2:$A1023, 0) ) / 1000000 ) * 'Shipments by country'!$J$2:$J1023, ('Shipments by country'!$E$2:$E1023 < NOW()) "&"* ('Shipments by country'!$I$2:$I1023 > 0) * ('Shipments by country'!$B$2:$B1023 = $A6) ) ), 0 )"),141.90961650977584) -> 141.90962 | AF6: =SUMIF('Shipments by country'!$B:$B,$A6,'Shipments by country'!$P:$P) -> 24124.99 | AG6: =IFERROR(__xludf.DUMMYFUNCTION("IFERROR( SUM( FILTER( 'Shipments by country'!$H$2:$H1023 * INDEX(Countries!$S$2:$S1023, MATCH('Shipments by country'!$B$2:$B1023, Countries!$A$2:$A1023, 0) ) / 1000000 "&" * 'Shipments by country'!$J$2:$J1023, ( 'Shipments by country'!$E$2:$E1023 < NOW() ) * ( 'Shipments by country'!$I$2:$I1023 > 0.25 ) * ( 'Shipments by country'!$"&"B$2:$B1023 = $A6 ) ) ), 0 ) "),48748.58636620977) -> 48748.586 | AH6: =SUMIF('Shipments by country'!$B:$B,$A6,'Shipments by country'!$Q:$Q) -> 11242.69 | AI6: =IFERROR(__xludf.DUMMYFUNCTION("IFERROR( SUM( FILTER( 'Shipments by country'!$H$2:$H1023 * ( INDEX(Countries!$T$2:$T1023, MATCH('Shipments by country'!$B$2:$B1023, Countries!$A$2:$A1023, 0) ) / 1000000 ) * 'Shipments by country"&"'!$J$2:$J1023, ('Shipments by country'!$E$2:$E1023 < NOW()) * ('Shipments by country'!$I$2:$I1023 > 0.25) * ('Shipments by country'!$B$2:$B1023 = $A6) ) ), 0 ) "),96.70234010788607) -> 96.70234 | AJ6: =SUMIF('Shipments by country'!$B:$B,$A6,'Shipments by country'!$R:$R) -> 21.119887 | AK6: =O6*4 -> 6356488.8 | AL6: =AK6*'Vaccine pricing'!B3 -> 19005902 | AM6: =IF($A6="","", LET( ctry,$A6, ctryCol,'Shipments by country'!$B$2:$B1023, vaccCol,'Shipments by country'!$C$2:$C1023, finCol,'Shipments by country'!$D$2:$D1023, doseCol,'Shipments by country'!$F$2:$F1023, price,IFERROR(VLOOKUP(vaccCol,'Vaccine pricing'!$A$2:$B1023,2,FALSE),0), totCost,SUMPRODUCT((ctryCol=ctry)*doseCol*price), gaviCost,SUMPRODUCT((ctryCol=ctry)*(finCol="Gavi")*doseCol*price), IF(totCost=0,"",gaviCost/totCost) )) -> 0.97858946 | AN6: 11 | AO6: 1271297.8 | AP6: 237 | AQ6: ='Vaccine pricing'!$B$3*4/((S6/1000000)*'Vaccine efficacy curves'!$C$3) -> 65.0727 | AR6: ='Vaccine pricing'!$B$3*4/((T6/1000000)*'Vaccine efficacy curves'!$C$3) -> 34639.968 | AS6: =K6/5 -> 433446.6 | AT6: =AS6*4 -> 1733786.4 | AU6: =AT6*'Vaccine pricing'!B3 -> 5184021.3 | AV6: =K6*31/60 -> 1119737.1 | AW6: =M6/AV6 -> 0.32274318 | AX6: =AV6-M6 -> 758349.55 | AY6: =1-AW6 -> 0.67725682 | AZ6: =AX6*4 -> 3033398.2 | BA6: =AZ6*'Vaccine pricing'!B3 -> 9069860.6 | BB6: 606679.64
A7: Cameroon | B7: =SUMIFS('Shipments by country'!F:F, 'Shipments by country'!B:B, A7, 'Shipments by country'!C:C, "RTS,S", 'Shipments by country'!G:G, "Delivered") -> 961800 | C7: =SUMIFS('Shipments by country'!F:F, 'Shipments by country'!B:B, A7, 'Shipments by country'!C:C, "R21", 'Shipments by country'!G:G, "Delivered") -> 0 | D7: =B7+C7 -> 961800 | E7: =SUMIFS('Shipments by country'!F:F, 'Shipments by country'!B:B, A7, 'Shipments by country'!C:C, "RTS,S") -> 1387900 | F7: =SUMIFS('Shipments by country'!F:F, 'Shipments by country'!B:B, A7, 'Shipments by country'!C:C, "R21") -> 0 | G7: =E7+F7 -> 1387900 | H7: Preparatory transition | I7: 23500000 | J7: 28372687 | K7: 4393101 | L7: =K7*0.9 -> 3953790.9 | M7: =G7/4 -> 346975 | N7: =M7/L7 -> 0.087757549 | O7: =L7-M7 -> 3606815.9 | P7: =1-N7 -> 0.91224245 | Q7: 7343057 | R7: 11602 | S7: =Q7*1000000/J7 -> 258807.25 | T7: =R7*1000000/J7 -> 408.91439 | U7: =IFERROR(__xludf.DUMMYFUNCTION("IFERROR( SUM( FILTER( 'Shipments by country'!$H$2:$H1023 * ( INDEX(Countries!$S$2:$S1023, MATCH('Shipments by country'!$B$2:$B1023, Countries!$A$2:$A1023, 0) ) / 1000000 ) * INDEX('Vaccine efficacy curves'!$C$2:$C1023, MATCH('Shipments by country'!$C$2:$C"&"1023, 'Vaccine efficacy curves'!$A$2:$A1023, 0) ), ('Shipments by country'!$E$2:$E1023 < NOW()) * ('Shipments by country'!$I$2:$I1023 > 0) * ('Shipments by country'!$B$2:$B1023 = $A7) ) ), 0 )"),67804.1096191503) -> 67804.11 | V7: =SUMIF('Shipments by country'!$B:$B,$A7,'Shipments by country'!$K:$K) -> 2559.4899 | W7: =IFERROR(__xludf.DUMMYFUNCTION("IFERROR( SUM( FILTER( 'Shipments by country'!$H$2:$H1023 * ( INDEX(Countries!$T$2:$T1023, MATCH('Shipments by country'!$B$2:$B1023, Countries!$A$2:$A1023, 0) ) / 1000000 ) * INDEX('Vaccine efficacy curves'!$C$2:$C1023, MATCH('Shipments by country'!$C$2:$C"&"1023, 'Vaccine efficacy curves'!$A$2:$A1023, 0) ), ('Shipments by country'!$E$2:$E1023 < NOW()) * ('Shipments by country'!$I$2:$I1023 > 0) * ('Shipments by country'!$B$2:$B1023 = $A7) ) ), 0 )"),134.50269141852158) -> 134.50269 | X7: =SUMIF('Shipments by country'!$B:$B,$A7,'Shipments by country'!$L:$L) -> 57094.857 | Y7: =IFERROR(__xludf.DUMMYFUNCTION("IFERROR( SUM( FILTER( 'Shipments by country'!$H$2:$H1023 * ( INDEX(Countries!$S$2:$S1023, MATCH('Shipments by country'!$B$2:$B1023, Countries!$A$2:$A1023, 0) ) / 1000000 ) * INDEX('Vaccine efficacy curves'!$C$2:$C1023, MATCH('Shipments by country'!$C$2:$C"&"1023, 'Vaccine efficacy curves'!$A$2:$A1023, 0) ), ('Shipments by country'!$E$2:$E1023 < NOW()) * ('Shipments by country'!$I$2:$I1023 > 0.25) * ('Shipments by country'!$B$2:$B1023 = $A7) ) ), 0 )"),67804.1096191503) -> 67804.11 | Z7: =SUMIF('Shipments by country'!$B:$B,$A7,'Shipments by country'!$M:$M) -> 2003.1334 | AA7: =IFERROR(__xludf.DUMMYFUNCTION("IFERROR( SUM( FILTER( 'Shipments by country'!$H$2:$H1023 * ( INDEX(Countries!$T$2:$T1023, MATCH('Shipments by country'!$B$2:$B1023, Countries!$A$2:$A1023, 0) ) / 1000000 ) * INDEX('Vaccine efficacy curves'!$C$2:$C1023, MATCH('Shipments by country'!$C$2:$C"&"1023, 'Vaccine efficacy curves'!$A$2:$A1023, 0) ), ('Shipments by country'!$E$2:$E1023 < NOW()) * ('Shipments by country'!$I$2:$I1023 > 0.25) * ('Shipments by country'!$B$2:$B1023 = $A7) ) ), 0 )"),134.50269141852158) -> 134.50269 | AB7: =SUMIF('Shipments by country'!$B:$B,$A7,'Shipments by country'!$N:$N) -> 44684.143 | AC7: =IFERROR(__xludf.DUMMYFUNCTION("IFERROR( SUM( FILTER( 'Shipments by country'!$H$2:$H1023 * ( INDEX(Countries!$S$2:$S1023, MATCH('Shipments by country'!$B$2:$B1023, Countries!$A$2:$A1023, 0) ) / 1000000 ) * 'Shipments by country'!$J$2:$J1023, ('Shipments by country'!$E$2:$E1023 < NOW()) "&"* ('Shipments by country'!$I$2:$I1023 > 0) * ('Shipments by country'!$B$2:$B1023 = $A7) ) ), 0 )"),64537.07067391035) -> 64537.071 | AD7: =SUMIF('Shipments by country'!$B:$B,$A7,'Shipments by country'!$O:$O) -> 2470.1325 | AE7: =IFERROR(__xludf.DUMMYFUNCTION("IFERROR( SUM( FILTER( 'Shipments by country'!$H$2:$H1023 * ( INDEX(Countries!$T$2:$T1023, MATCH('Shipments by country'!$B$2:$B1023, Countries!$A$2:$A1023, 0) ) / 1000000 ) * 'Shipments by country'!$J$2:$J1023, ('Shipments by country'!$E$2:$E1023 < NOW()) "&"* ('Shipments by country'!$I$2:$I1023 > 0) * ('Shipments by country'!$B$2:$B1023 = $A7) ) ), 0 )"),128.02188172170358) -> 128.02188 | AF7: =SUMIF('Shipments by country'!$B:$B,$A7,'Shipments by country'!$P:$P) -> 55101.551 | AG7: =IFERROR(__xludf.DUMMYFUNCTION("IFERROR( SUM( FILTER( 'Shipments by country'!$H$2:$H1023 * INDEX(Countries!$S$2:$S1023, MATCH('Shipments by country'!$B$2:$B1023, Countries!$A$2:$A1023, 0) ) / 1000000 "&" * 'Shipments by country'!$J$2:$J1023, ( 'Shipments by country'!$E$2:$E1023 < NOW() ) * ( 'Shipments by country'!$I$2:$I1023 > 0.25 ) * ( 'Shipments by country'!$"&"B$2:$B1023 = $A7 ) ) ), 0 ) "),64537.07067391035) -> 64537.071 | AH7: =SUMIF('Shipments by country'!$B:$B,$A7,'Shipments by country'!$Q:$Q) -> 11782.006 | AI7: =IFERROR(__xludf.DUMMYFUNCTION("IFERROR( SUM( FILTER( 'Shipments by country'!$H$2:$H1023 * ( INDEX(Countries!$T$2:$T1023, MATCH('Shipments by country'!$B$2:$B1023, Countries!$A$2:$A1023, 0) ) / 1000000 ) * 'Shipments by country"&"'!$J$2:$J1023, ('Shipments by country'!$E$2:$E1023 < NOW()) * ('Shipments by country'!$I$2:$I1023 > 0.25) * ('Shipments by country'!$B$2:$B1023 = $A7) ) ), 0 ) "),128.02188172170358) -> 128.02188 | AJ7: =SUMIF('Shipments by country'!$B:$B,$A7,'Shipments by country'!$R:$R) -> 18.615521 | AK7: =O7*4 -> 14427264 | AL7: =AK7*'Vaccine pricing'!B3 -> 43137518 | AM7: =IF($A7="","", LET( ctry,$A7, ctryCol,'Shipments by country'!$B$2:$B1023, vaccCol,'Shipments by country'!$C$2:$C1023, finCol,'Shipments by country'!$D$2:$D1023, doseCol,'Shipments by country'!$F$2:$F1023, price,IFERROR(VLOOKUP(vaccCol,'Vaccine pricing'!$A$2:$B1023,2,FALSE),0), totCost,SUMPRODUCT((ctryCol=ctry)*doseCol*price), gaviCost,SUMPRODUCT((ctryCol=ctry)*(finCol="Gavi")*doseCol*price), IF(totCost=0,"",gaviCost/totCost) )) -> 0.97708769 | AN7: 11 | AO7: 11673266 | AP7: 1633 | AQ7: ='Vaccine pricing'!$B$3*4/((S7/1000000)*'Vaccine efficacy curves'!$C$3) -> 61.615998 | AR7: ='Vaccine pricing'!$B$3*4/((T7/1000000)*'Vaccine efficacy curves'!$C$3) -> 38997.568 | AS7: =K7/5 -> 878620.2 | AT7: =AS7*4 -> 3514480.8 | AU7: =AT7*'Vaccine pricing'!B3 -> 10508298 | AV7: =K7*31/60 -> 2269768.9 | AW7: =M7/AV7 -> 0.15286799 | AX7: =AV7-M7 -> 1922793.9 | AY7: =1-AW7 -> 0.84713201 | AZ7: =AX7*4 -> 7691175.4 | BA7: =AZ7*'Vaccine pricing'!B3 -> 22996614 | BB7: 6223018.8
A8: Central African Republic | B8: =SUMIFS('Shipments by country'!F:F, 'Shipments by country'!B:B, A8, 'Shipments by country'!C:C, "RTS,S", 'Shipments by country'!G:G, "Delivered") -> 0 | C8: =SUMIFS('Shipments by country'!F:F, 'Shipments by country'!B:B, A8, 'Shipments by country'!C:C, "R21", 'Shipments by country'!G:G, "Delivered") -> 430400 | D8: =B8+C8 -> 430400 | E8: =SUMIFS('Shipments by country'!F:F, 'Shipments by country'!B:B, A8, 'Shipments by country'!C:C, "RTS,S") -> 0 | F8: =SUMIFS('Shipments by country'!F:F, 'Shipments by country'!B:B, A8, 'Shipments by country'!C:C, "R21") -> 452200 | G8: =E8+F8 -> 452200 | H8: Initial self-financing | I8: 0 | J8: 5152420 | K8: 940906 | L8: =K8*0.9 -> 846815.4 | M8: =G8/4 -> 113050 | N8: =M8/L8 -> 0.13350017 | O8: =L8-M8 -> 733765.4 | P8: =1-N8 -> 0.86649983 | Q8: 1574284 | R8: 5052 | S8: =Q8*1000000/J8 -> 305542.64 | T8: =R8*1000000/J8 -> 980.51013 | U8: =IFERROR(__xludf.DUMMYFUNCTION("IFERROR( SUM( FILTER( 'Shipments by country'!$H$2:$H1023 * ( INDEX(Countries!$S$2:$S1023, MATCH('Shipments by country'!$B$2:$B1023, Countries!$A$2:$A1023, 0) ) / 1000000 ) * INDEX('Vaccine efficacy curves'!$C$2:$C1023, MATCH('Shipments by country'!$C$2:$C"&"1023, 'Vaccine efficacy curves'!$A$2:$A1023, 0) ), ('Shipments by country'!$E$2:$E1023 < NOW()) * ('Shipments by country'!$I$2:$I1023 > 0) * ('Shipments by country'!$B$2:$B1023 = $A8) ) ), 0 )"),21299.823939918464) -> 21299.824 | V8: =SUMIF('Shipments by country'!$B:$B,$A8,'Shipments by country'!$K:$K) -> 354.63856 | W8: =IFERROR(__xludf.DUMMYFUNCTION("IFERROR( SUM( FILTER( 'Shipments by country'!$H$2:$H1023 * ( INDEX(Countries!$T$2:$T1023, MATCH('Shipments by country'!$B$2:$B1023, Countries!$A$2:$A1023, 0) ) / 1000000 ) * INDEX('Vaccine efficacy curves'!$C$2:$C1023, MATCH('Shipments by country'!$C$2:$C"&"1023, 'Vaccine efficacy curves'!$A$2:$A1023, 0) ), ('Shipments by country'!$E$2:$E1023 < NOW()) * ('Shipments by country'!$I$2:$I1023 > 0) * ('Shipments by country'!$B$2:$B1023 = $A8) ) ), 0 )"),42.252359963894385) -> 42.25236 | X8: =SUMIF('Shipments by country'!$B:$B,$A8,'Shipments by country'!$L:$L) -> 21448.377 | Y8: =IFERROR(__xludf.DUMMYFUNCTION("IFERROR( SUM( FILTER( 'Shipments by country'!$H$2:$H1023 * ( INDEX(Countries!$S$2:$S1023, MATCH('Shipments by country'!$B$2:$B1023, Countries!$A$2:$A1023, 0) ) / 1000000 ) * INDEX('Vaccine efficacy curves'!$C$2:$C1023, MATCH('Shipments by country'!$C$2:$C"&"1023, 'Vaccine efficacy curves'!$A$2:$A1023, 0) ), ('Shipments by country'!$E$2:$E1023 < NOW()) * ('Shipments by country'!$I$2:$I1023 > 0.25) * ('Shipments by country'!$B$2:$B1023 = $A8) ) ), 0 )"),21299.823939918464) -> 21299.824 | Z8: =SUMIF('Shipments by country'!$B:$B,$A8,'Shipments by country'!$M:$M) -> 252.71446 | AA8: =IFERROR(__xludf.DUMMYFUNCTION("IFERROR( SUM( FILTER( 'Shipments by country'!$H$2:$H1023 * ( INDEX(Countries!$T$2:$T1023, MATCH('Shipments by country'!$B$2:$B1023, Countries!$A$2:$A1023, 0) ) / 1000000 ) * INDEX('Vaccine efficacy curves'!$C$2:$C1023, MATCH('Shipments by country'!$C$2:$C"&"1023, 'Vaccine efficacy curves'!$A$2:$A1023, 0) ), ('Shipments by country'!$E$2:$E1023 < NOW()) * ('Shipments by country'!$I$2:$I1023 > 0.25) * ('Shipments by country'!$B$2:$B1023 = $A8) ) ), 0 )"),42.252359963894385) -> 42.25236 | AB8: =SUMIF('Shipments by country'!$B:$B,$A8,'Shipments by country'!$N:$N) -> 15284.055 | AC8: =IFERROR(__xludf.DUMMYFUNCTION("IFERROR( SUM( FILTER( 'Shipments by country'!$H$2:$H1023 * ( INDEX(Countries!$S$2:$S1023, MATCH('Shipments by country'!$B$2:$B1023, Countries!$A$2:$A1023, 0) ) / 1000000 ) * 'Shipments by country'!$J$2:$J1023, ('Shipments by country'!$E$2:$E1023 < NOW()) "&"* ('Shipments by country'!$I$2:$I1023 > 0) * ('Shipments by country'!$B$2:$B1023 = $A8) ) ), 0 )"),27860.751378014094) -> 27860.751 | AD8: =SUMIF('Shipments by country'!$B:$B,$A8,'Shipments by country'!$O:$O) -> 346.709 | AE8: =IFERROR(__xludf.DUMMYFUNCTION("IFERROR( SUM( FILTER( 'Shipments by country'!$H$2:$H1023 * ( INDEX(Countries!$T$2:$T1023, MATCH('Shipments by country'!$B$2:$B1023, Countries!$A$2:$A1023, 0) ) / 1000000 ) * 'Shipments by country'!$J$2:$J1023, ('Shipments by country'!$E$2:$E1023 < NOW()) "&"* ('Shipments by country'!$I$2:$I1023 > 0) * ('Shipments by country'!$B$2:$B1023 = $A8) ) ), 0 )"),55.26724067809006) -> 55.267241 | AF8: =SUMIF('Shipments by country'!$B:$B,$A8,'Shipments by country'!$P:$P) -> 20968.801 | AG8: =IFERROR(__xludf.DUMMYFUNCTION("IFERROR( SUM( FILTER( 'Shipments by country'!$H$2:$H1023 * INDEX(Countries!$S$2:$S1023, MATCH('Shipments by country'!$B$2:$B1023, Countries!$A$2:$A1023, 0) ) / 1000000 "&" * 'Shipments by country'!$J$2:$J1023, ( 'Shipments by country'!$E$2:$E1023 < NOW() ) * ( 'Shipments by country'!$I$2:$I1023 > 0.25 ) * ( 'Shipments by country'!$"&"B$2:$B1023 = $A8 ) ) ), 0 ) "),27860.751378014094) -> 27860.751 | AH8: =SUMIF('Shipments by country'!$B:$B,$A8,'Shipments by country'!$Q:$Q) -> 5912.9662 | AI8: =IFERROR(__xludf.DUMMYFUNCTION("IFERROR( SUM( FILTER( 'Shipments by country'!$H$2:$H1023 * ( INDEX(Countries!$T$2:$T1023, MATCH('Shipments by country'!$B$2:$B1023, Countries!$A$2:$A1023, 0) ) / 1000000 ) * 'Shipments by country"&"'!$J$2:$J1023, ('Shipments by country'!$E$2:$E1023 < NOW()) * ('Shipments by country'!$I$2:$I1023 > 0.25) * ('Shipments by country'!$B$2:$B1023 = $A8) ) ), 0 ) "),55.26724067809006) -> 55.267241 | AJ8: =SUMIF('Shipments by country'!$B:$B,$A8,'Shipments by country'!$R:$R) -> 18.975169 | AK8: =O8*4 -> 2935061.6 | AL8: =AK8*'Vaccine pricing'!B3 -> 8775834.2 | AM8: =IF($A8="","", LET( ctry,$A8, ctryCol,'Shipments by country'!$B$2:$B1023, vaccCol,'Shipments by country'!$C$2:$C1023, finCol,'Shipments by country'!$D$2:$D1023, doseCol,'Shipments by country'!$F$2:$F1023, price,IFERROR(VLOOKUP(vaccCol,'Vaccine pricing'!$A$2:$B1023,2,FALSE),0), totCost,SUMPRODUCT((ctryCol=ctry)*doseCol*price), gaviCost,SUMPRODUCT((ctryCol=ctry)*(finCol="Gavi")*doseCol*price), IF(totCost=0,"",gaviCost/totCost) )) -> 0.95179124 | AN8: 11 | AO8: 587012.32 | AP8: 493 | AQ8: ='Vaccine pricing'!$B$3*4/((S8/1000000)*'Vaccine efficacy curves'!$C$3) -> 52.191297 | AR8: ='Vaccine pricing'!$B$3*4/((T8/1000000)*'Vaccine efficacy curves'!$C$3) -> 16263.643 | AS8: =K8/5 -> 188181.2 | AT8: =AS8*4 -> 752724.8 | AU8: =AT8*'Vaccine pricing'!B3 -> 2250647.2 | AV8: =K8*31/60 -> 486134.77 | AW8: =M8/AV8 -> 0.23254868 | AX8: =AV8-M8 -> 373084.77 | AY8: =1-AW8 -> 0.76745132 | AZ8: =AX8*4 -> 1492339.1 | BA8: =AZ8*'Vaccine pricing'!B3 -> 4462093.8 | BB8: 298467.81
